Workbook
Name Consolidado: CONSOLIDADO!$C$13:$H$27

Sheet CONSOLIDADO
C1: MATRIZ DE INDICADORES SALUD PÚBLICA | L1: Fuente de datos: ASIS municipal, oficina de epidemiología o vigilancia en salud publica de cada municipio.
B2: RECOMENDACIONES. TODOS LOS VALORES ESTAN FORMULADOS, Y SON FORMULACION ESTANDAR INTERNACIONAL. LA FUENTE DE POBLACION DE REFERENCIA ES DANE AJUSTE COVID 2021. EN ALGUNOS INDICADORES DEBE SUMAR MUERTES FETALES A NACIMIENTOS PARA AJUSTAR DENOMINADOR. LAS FUENTES UTILIZADAS SON LAS MAS RELEVANTES, SI POSEE OTRA FUENTE DE INFORMACION INCLUYALA Y MODIFIQUE LA FUENTE. | L2: INDICADOR | M2: CASOS 2020 | N2: VALOR DEL INDICADOR 2020 CORTE 31/12/2020 | O2: CASOS 2021 | P2: VALOR DEL INDICADOR 2021 corte 31/12/2021 mortalidad | Q2: CASOS 2022 | R2: VALOR DEL INDICADOR 2022 | S2: CASOS 2023 | T2: VALOR DEL INDICADOR 2023 31-12-2023 | U2: CASOS 2024 | V2: VALOR DEL INDICADOR 2024 preliminar 31-12-2024 | W2: CASOS 2025 | X2: VALOR DEL INDICADOR 2024 preliminar 24-06-2025 | Y2: VALOR PROMEDIO INDICADOR CUATRENIO ANTERIOR | Z2: VALOR PROMEDIO CASOS CUATRENIO ANTERIOR | AA2: VALOR PROMEDIO INDICADOR PERIODO 2024-2025 | AB2: VALOR PROMEDIO CASOS PERIODO ACTUAL 2024-2025 | AC2: FUENTE
L3: TASA DE MORTALIDAD | M3: =CAJICA!M3+COTA!M4+CHIA!M3+ZIPAQUIRA!M3+TABIO!M3+TENJO!M3+SOPO!M3+GACHANCIPA!M3+TOCANCIPA!M3+NEMOCON!M3+COGUA!M3 -> 2236 | N3: =M3/C7*1000 -> 4.999251 | O3: =CAJICA!O3+COTA!O4+CHIA!O3+ZIPAQUIRA!O3+TABIO!O3+TENJO!O3+SOPO!O3+GACHANCIPA!O3+TOCANCIPA!O3+NEMOCON!O3+COGUA!O3 -> 3023 | P3: =O3/D7*1000 -> 6.5380115 | Q3: =CAJICA!Q3+COTA!Q4+CHIA!Q3+ZIPAQUIRA!Q3+TABIO!Q3+TENJO!Q3+SOPO!Q3+GACHANCIPA!Q3+TOCANCIPA!Q3+NEMOCON!Q3+COGUA!Q3 -> 2320 | R3: =Q3/E7*1000 -> 4.8645169 | S3: =CAJICA!S3+COTA!S4+CHIA!S3+ZIPAQUIRA!S3+TABIO!S3+TENJO!S3+SOPO!S3+GACHANCIPA!S3+TOCANCIPA!S3+NEMOCON!S3+COGUA!S3 -> 2081 | T3: =S3/F7*1000 -> 4.2312744 | U3: =CAJICA!U3+COTA!U4+CHIA!U3+ZIPAQUIRA!U3+TABIO!U3+TENJO!U3+SOPO!U3+GACHANCIPA!U3+TOCANCIPA!U3+NEMOCON!U3+COGUA!U3 -> 2195 | V3: =U3/G7*1000 -> #VALUE! | W3: =CAJICA!W3+COTA!W4+CHIA!W3+ZIPAQUIRA!W3+TABIO!W3+TENJO!W3+SOPO!W3+GACHANCIPA!W3+TOCANCIPA!W3+NEMOCON!W3+COGUA!W3 -> 1019 | X3: =W3/H7*1000 -> 1.957906 | Y3: =((M3+O3+Q3+S3)/4) -> 2415 | Z3: =((N3+P3+R3+T3)/4) -> 5.1582635 | AA3: =((S3+U3)/2) -> 2138 | AB3: =(V3+X3)/2 -> #VALUE! | AC3: DANE
L4: TASA DE NATALIDAD | M4: =CAJICA!M4+COTA!M5+CHIA!M4+ZIPAQUIRA!M4+TABIO!M4+TENJO!M4+SOPO!M4+GACHANCIPA!M4+TOCANCIPA!M4+NEMOCON!M4+COGUA!M4 -> 4165 | N4: =M4/C7*1000 -> 9.3121111 | O4: =CAJICA!O4+COTA!O5+CHIA!O4+ZIPAQUIRA!O4+TABIO!O4+TENJO!O4+SOPO!O4+GACHANCIPA!O4+TOCANCIPA!O4+NEMOCON!O4+COGUA!O4 -> 4618 | P4: =O4/D7*1000 -> 9.9876074 | Q4: =CAJICA!Q4+COTA!Q5+CHIA!Q4+ZIPAQUIRA!Q4+TABIO!Q4+TENJO!Q4+SOPO!Q4+GACHANCIPA!Q4+TOCANCIPA!Q4+NEMOCON!Q4+COGUA!Q4 -> 4758 | R4: =Q4/E7*1000 -> 9.9764532 | S4: =CAJICA!S4+COTA!S5+CHIA!S4+ZIPAQUIRA!S4+TABIO!S4+TENJO!S4+SOPO!S4+GACHANCIPA!S4+TOCANCIPA!S4+NEMOCON!S4+COGUA!S4 -> 4255 | T4: =S4/F7*1000 -> 8.6516447 | U4: =CAJICA!U4+COTA!U5+CHIA!U4+ZIPAQUIRA!U4+TABIO!U4+TENJO!U4+SOPO!U4+GACHANCIPA!U4+TOCANCIPA!U4+NEMOCON!U4+COGUA!U4 -> 4338 | V4: =U4/G7*1000 -> #VALUE! | W4: =CAJICA!W4+COTA!W5+CHIA!W4+ZIPAQUIRA!W4+TABIO!W4+TENJO!W4+SOPO!W4+GACHANCIPA!W4+TOCANCIPA!W4+NEMOCON!W4+COGUA!W4 -> 1850 | X4: =W4/H7*1000 -> 3.5545889 | Y4: =((M4+O4+Q4+S4)/4) -> 4449 | Z4: =((N4+P4+R4+T4)/4) -> 9.4819541 | AA4: =((S4+U4)/2) -> 4296.5 | AB4: =(V4+X4)/2 -> #VALUE! | AC4: RUAF
B5: RANGO EDAD | C5: AÑO 2020 | D5: AÑO 2021 | E5: AÑO 2022 | F5: AÑO 2023 | G5: AÑO 2024 | H5: AÑO 2025 | L5: RAZON DE MORTALIDAD MATERNA | M5: =CAJICA!M5+COTA!M6+CHIA!M5+ZIPAQUIRA!M5+TABIO!M5+TENJO!M5+SOPO!M5+GACHANCIPA!M5+TOCANCIPA!M5+NEMOCON!M5+COGUA!M5 -> 23 | N5: =M5/C12*100000 -> 509.30027 | O5: =CAJICA!O5+COTA!O6+CHIA!O5+ZIPAQUIRA!O5+TABIO!O5+TENJO!O5+SOPO!O5+GACHANCIPA!O5+TOCANCIPA!O5+NEMOCON!O5+COGUA!O5 -> 18 | P5: =O5/D12*100000 -> 364.07767 | Q5: =CAJICA!Q5+COTA!Q6+CHIA!Q5+ZIPAQUIRA!Q5+TABIO!Q5+TENJO!Q5+SOPO!Q5+GACHANCIPA!Q5+TOCANCIPA!Q5+NEMOCON!Q5+COGUA!Q5 -> 9 | R5: =Q5/E12*100000 -> 177.30496 | S5: =CAJICA!S5+COTA!S6+CHIA!S5+ZIPAQUIRA!S5+TABIO!S5+TENJO!S5+SOPO!S5+GACHANCIPA!S5+TOCANCIPA!S5+NEMOCON!S5+COGUA!S5 -> 17 | T5: =S5/F12*100000 -> 371.5847 | U5: =CAJICA!U5+COTA!U6+CHIA!U5+ZIPAQUIRA!U5+TABIO!U5+TENJO!U5+SOPO!U5+GACHANCIPA!U5+TOCANCIPA!U5+NEMOCON!U5+COGUA!U5 -> 19 | V5: =U5/G12*100000 -> 409.04198 | W5: =CAJICA!W5+COTA!W6+CHIA!W5+ZIPAQUIRA!W5+TABIO!W5+TENJO!W5+SOPO!W5+GACHANCIPA!W5+TOCANCIPA!W5+NEMOCON!W5+COGUA!W5 -> 4 | X5: =W5/H12*100000 -> 221.85247 | Y5: =((M5+O5+Q5+S5)/4) -> 16.75 | Z5: =((N5+P5+R5+T5)/4) -> 355.5669 | AA5: =((S5+U5)/2) -> 18 | AB5: =(V5+X5)/2 -> 315.44722 | AC5: DANE - RUAF
L6: RAZON DE MORTALIDAD FETAL | M6: =CAJICA!M6+COTA!M7+CHIA!M6+ZIPAQUIRA!M6+TABIO!M6+TENJO!M6+SOPO!M6+GACHANCIPA!M6+TOCANCIPA!M6+NEMOCON!M6+COGUA!M6 -> 157 | N6: =M6/M4*1000 -> 37.695078 | O6: =CAJICA!O6+COTA!O7+CHIA!O6+ZIPAQUIRA!O6+TABIO!O6+TENJO!O6+SOPO!O6+GACHANCIPA!O6+TOCANCIPA!O6+NEMOCON!O6+COGUA!O6 -> 204 | P6: =O6/O4*1000 -> 44.174968 | Q6: =CAJICA!Q6+COTA!Q7+CHIA!Q6+ZIPAQUIRA!Q6+TABIO!Q6+TENJO!Q6+SOPO!Q6+GACHANCIPA!Q6+TOCANCIPA!Q6+NEMOCON!Q6+COGUA!Q6 -> 125 | R6: =Q6/Q4*1000 -> 26.271543 | S6: =CAJICA!S6+COTA!S7+CHIA!S6+ZIPAQUIRA!S6+TABIO!S6+TENJO!S6+SOPO!S6+GACHANCIPA!S6+TOCANCIPA!S6+NEMOCON!S6+COGUA!S6 -> 108 | T6: =S6/S4*1000 -> 25.381904 | U6: =CAJICA!U6+COTA!U7+CHIA!U6+ZIPAQUIRA!U6+TABIO!U6+TENJO!U6+SOPO!U6+GACHANCIPA!U6+TOCANCIPA!U6+NEMOCON!U6+COGUA!U6 -> 83 | V6: =U6/U4*1000 -> 19.133241 | W6: =CAJICA!W6+COTA!W7+CHIA!W6+ZIPAQUIRA!W6+TABIO!W6+TENJO!W6+SOPO!W6+GACHANCIPA!W6+TOCANCIPA!W6+NEMOCON!W6+COGUA!W6 -> 54 | X6: =W6/W4*1000 -> 29.189189 | Y6: =((M6+O6+Q6+S6)/4) -> 148.5 | Z6: =((N6+P6+R6+T6)/4) -> 33.380873 | AA6: =((S6+U6)/2) -> 95.5 | AB6: =(V6+X6)/2 -> 24.161215 | AC6: DANE
B7: POBLACION TOTAL | C7: =CAJICA!C7+COTA!C7+CHIA!C7+ZIPAQUIRA!C7+TABIO!C7+TENJO!C7+SOPO!C7+GACHANCIPA!C7+TOCANCIPA!C7+NEMOCON!C7+COGUA!C7 -> 447267 | D7: =CAJICA!D7+COTA!D7+CHIA!D7+ZIPAQUIRA!D7+TABIO!D7+TENJO!D7+SOPO!D7+GACHANCIPA!D7+TOCANCIPA!D7+NEMOCON!D7+COGUA!D7 -> 462373 | E7: =CAJICA!E7+COTA!E7+CHIA!E7+ZIPAQUIRA!E7+TABIO!E7+TENJO!E7+SOPO!E7+GACHANCIPA!E7+TOCANCIPA!E7+NEMOCON!E7+COGUA!E7 -> 476923 | F7: =CAJICA!F7+COTA!F7+CHIA!F7+ZIPAQUIRA!F7+TABIO!F7+TENJO!F7+SOPO!F7+GACHANCIPA!F7+TOCANCIPA!F7+NEMOCON!F7+COGUA!F7 -> 491814 | G7: =CAJICA!G7+COTA!G7+CHIA!G7+ZIPAQUIRA!G7+TABIO!G7+TENJO!G7+SOPO!G7+GACHANCIPA!G7+TOCANCIPA!G7+NEMOCON!G7+COGUA!G7 -> #VALUE! | H7: =CAJICA!H7+COTA!H7+CHIA!H7+ZIPAQUIRA!H7+TABIO!H7+TENJO!H7+SOPO!H7+GACHANCIPA!H7+TOCANCIPA!H7+NEMOCON!H7+COGUA!H7 -> 520454 | L7: RAZON DE MORTALIDAD PERINATAL | M7: =CAJICA!M7+COTA!M8+CHIA!M7+ZIPAQUIRA!M7+TABIO!M7+TENJO!M7+SOPO!M7+GACHANCIPA!M7+TOCANCIPA!M7+NEMOCON!M7+COGUA!M7 -> 54 | N7: =CAJICA!N7+COTA!N7+CHIA!N7+ZIPAQUIRA!N7+TABIO!N7+TENJO!N7+SOPO!N7+GACHANCIPA!N7+TOCANCIPA!N7+NEMOCON!N7+COGUA!N7 -> 12.195122 | O7: =CAJICA!O7+COTA!O8+CHIA!O7+ZIPAQUIRA!O7+TABIO!O7+TENJO!O7+SOPO!O7+GACHANCIPA!O7+TOCANCIPA!O7+NEMOCON!O7+COGUA!O7 -> 43 | P7: =CAJICA!P7+COTA!P7+CHIA!P7+ZIPAQUIRA!P7+TABIO!P7+TENJO!P7+SOPO!P7+GACHANCIPA!P7+TOCANCIPA!P7+NEMOCON!P7+COGUA!P7 -> 6.6964286 | Q7: =CAJICA!Q7+COTA!Q8+CHIA!Q7+ZIPAQUIRA!Q7+TABIO!Q7+TENJO!Q7+SOPO!Q7+GACHANCIPA!Q7+TOCANCIPA!Q7+NEMOCON!Q7+COGUA!Q7 -> 52 | R7: =CAJICA!R7+COTA!R7+CHIA!R7+ZIPAQUIRA!R7+TABIO!R7+TENJO!R7+SOPO!R7+GACHANCIPA!R7+TOCANCIPA!R7+NEMOCON!R7+COGUA!R7 -> 5.7208238 | S7: =CAJICA!S7+COTA!S8+CHIA!S7+ZIPAQUIRA!S7+TABIO!S7+TENJO!S7+SOPO!S7+GACHANCIPA!S7+TOCANCIPA!S7+NEMOCON!S7+COGUA!S7 -> 40 | T7: =CAJICA!T7+COTA!T7+CHIA!T7+ZIPAQUIRA!T7+TABIO!T7+TENJO!T7+SOPO!T7+GACHANCIPA!T7+TOCANCIPA!T7+NEMOCON!T7+COGUA!T7 -> 14.051522 | U7: =CAJICA!U7+COTA!U8+CHIA!U7+ZIPAQUIRA!U7+TABIO!U7+TENJO!U7+SOPO!U7+GACHANCIPA!U7+TOCANCIPA!U7+NEMOCON!U7+COGUA!U7 -> 54 | V7: =CAJICA!V7+COTA!V7+CHIA!V7+ZIPAQUIRA!V7+TABIO!V7+TENJO!V7+SOPO!V7+GACHANCIPA!V7+TOCANCIPA!V7+NEMOCON!V7+COGUA!V7 -> 9.3131548 | W7: =CAJICA!W7+COTA!W8+CHIA!W7+ZIPAQUIRA!W7+TABIO!W7+TENJO!W7+SOPO!W7+GACHANCIPA!W7+TOCANCIPA!W7+NEMOCON!W7+COGUA!W7 -> 36 | X7: =CAJICA!X7+COTA!X7+CHIA!X7+ZIPAQUIRA!X7+TABIO!X7+TENJO!X7+SOPO!X7+GACHANCIPA!X7+TOCANCIPA!X7+NEMOCON!X7+COGUA!X7 -> 21.276596 | Y7: =((M7+O7+Q7+S7)/4) -> 47.25 | Z7: =((N7+P7+R7+T7)/4) -> 9.6659741 | AA7: =((S7+U7)/2) -> 47 | AB7: =(V7+X7)/2 -> 15.294875 | AC7: DANE - SIVIGILA
B8: POBLACION TOTAL CABECERA | C8: =CAJICA!C8+COTA!C8+CHIA!C8+ZIPAQUIRA!C8+TABIO!C8+TENJO!C8+SOPO!C8+GACHANCIPA!C8+TOCANCIPA!C8+NEMOCON!C8+COGUA!C8 -> 293901 | D8: =CAJICA!D8+COTA!D8+CHIA!D8+ZIPAQUIRA!D8+TABIO!D8+TENJO!D8+SOPO!D8+GACHANCIPA!D8+TOCANCIPA!D8+NEMOCON!D8+COGUA!D8 -> 310406 | E8: =CAJICA!E8+COTA!E8+CHIA!E8+ZIPAQUIRA!E8+TABIO!E8+TENJO!E8+SOPO!E8+GACHANCIPA!E8+TOCANCIPA!E8+NEMOCON!E8+COGUA!E8 -> 324738 | F8: =CAJICA!F8+COTA!F8+CHIA!F8+ZIPAQUIRA!F8+TABIO!F8+TENJO!F8+SOPO!F8+GACHANCIPA!F8+TOCANCIPA!F8+NEMOCON!F8+COGUA!F8 -> 265135 | G8: =CAJICA!G8+COTA!G8+CHIA!G8+ZIPAQUIRA!G8+TABIO!G8+TENJO!G8+SOPO!G8+GACHANCIPA!G8+TOCANCIPA!G8+NEMOCON!G8+COGUA!G8 -> 275496 | H8: =CAJICA!H8+COTA!H8+CHIA!H8+ZIPAQUIRA!H8+TABIO!H8+TENJO!H8+SOPO!H8+GACHANCIPA!H8+TOCANCIPA!H8+NEMOCON!H8+COGUA!H8 -> 285257 | L8: TASA DE MORTALIDAD POR DESNUTRICION < 5 AÑOS | M8: =CAJICA!M8+COTA!M9+CHIA!M8+ZIPAQUIRA!M8+TABIO!M8+TENJO!M8+SOPO!M8+GACHANCIPA!M8+TOCANCIPA!M8+NEMOCON!M8+COGUA!M8 -> 4 | N8: =M8/C15*1000 -> 0.10196246 | O8: =CAJICA!O8+COTA!O9+CHIA!O8+ZIPAQUIRA!O8+TABIO!O8+TENJO!O8+SOPO!O8+GACHANCIPA!O8+TOCANCIPA!O8+NEMOCON!O8+COGUA!O8 -> 4 | P8: =O8/D15*1000 -> 0.099262465 | Q8: =CAJICA!Q8+COTA!Q9+CHIA!Q8+ZIPAQUIRA!Q8+TABIO!Q8+TENJO!Q8+SOPO!Q8+GACHANCIPA!Q8+TOCANCIPA!Q8+NEMOCON!Q8+COGUA!Q8 -> 6 | R8: =Q8/E15*1000 -> 0.14627275 | S8: =CAJICA!S8+COTA!S9+CHIA!S8+ZIPAQUIRA!S8+TABIO!S8+TENJO!S8+SOPO!S8+GACHANCIPA!S8+TOCANCIPA!S8+NEMOCON!S8+COGUA!S8 -> 8 | T8: =S8/F15*1000 -> 0.19666988 | U8: =CAJICA!U8+COTA!U9+CHIA!U8+ZIPAQUIRA!U8+TABIO!U8+TENJO!U8+SOPO!U8+GACHANCIPA!U8+TOCANCIPA!U8+NEMOCON!U8+COGUA!U8 -> 12 | V8: =U8/G15*1000 -> 0.29511391 | W8: =CAJICA!W8+COTA!W9+CHIA!W8+ZIPAQUIRA!W8+TABIO!W8+TENJO!W8+SOPO!W8+GACHANCIPA!W8+TOCANCIPA!W8+NEMOCON!W8+COGUA!W8 -> 7 | X8: =W8/H15*1000 -> 0.17150452 | Y8: =((M8+O8+Q8+S8)/4) -> 5.5 | Z8: =((N8+P8+R8+T8)/4) -> 0.13604189 | AA8: =((S8+U8)/2) -> 10 | AB8: =(V8+X8)/2 -> 0.23330922 | AC8: DANE - SIVIGILA
B9: POBLACION TOTAL RURAL DISPERSA | C9: =CAJICA!C9+COTA!C9+CHIA!C9+ZIPAQUIRA!C9+TABIO!C9+TENJO!C9+SOPO!C9+GACHANCIPA!C9+TOCANCIPA!C9+NEMOCON!C9+COGUA!C9 -> 156840 | D9: =CAJICA!D9+COTA!D9+CHIA!D9+ZIPAQUIRA!D9+TABIO!D9+TENJO!D9+SOPO!D9+GACHANCIPA!D9+TOCANCIPA!D9+NEMOCON!D9+COGUA!D9 -> 154320 | E9: =CAJICA!E9+COTA!E9+CHIA!E9+ZIPAQUIRA!E9+TABIO!E9+TENJO!E9+SOPO!E9+GACHANCIPA!E9+TOCANCIPA!E9+NEMOCON!E9+COGUA!E9 -> 156648 | F9: =CAJICA!F9+COTA!F9+CHIA!F9+ZIPAQUIRA!F9+TABIO!F9+TENJO!F9+SOPO!F9+GACHANCIPA!F9+TOCANCIPA!F9+NEMOCON!F9+COGUA!F9 -> 128238 | G9: =CAJICA!G9+COTA!G9+CHIA!G9+ZIPAQUIRA!G9+TABIO!G9+TENJO!G9+SOPO!G9+GACHANCIPA!G9+TOCANCIPA!G9+NEMOCON!G9+COGUA!G9 -> 129343 | H9: =CAJICA!H9+COTA!H9+CHIA!H9+ZIPAQUIRA!H9+TABIO!H9+TENJO!H9+SOPO!H9+GACHANCIPA!H9+TOCANCIPA!H9+NEMOCON!H9+COGUA!H9 -> 130599 | L9: TASA DE MORTALIDAD BRUTA POR CAUSA EXTERNA | M9: =CAJICA!M9+COTA!M10+CHIA!M9+ZIPAQUIRA!M9+TABIO!M9+TENJO!M9+SOPO!M9+GACHANCIPA!M9+TOCANCIPA!M9+NEMOCON!M9+COGUA!M9 -> 101 | N9: =M9/C7*100000 -> 22.58159 | O9: =CAJICA!O9+COTA!O10+CHIA!O9+ZIPAQUIRA!O9+TABIO!O9+TENJO!O9+SOPO!O9+GACHANCIPA!O9+TOCANCIPA!O9+NEMOCON!O9+COGUA!O9 -> 152 | P9: =O9/D7*100000 -> 32.873892 | Q9: =CAJICA!Q9+COTA!Q10+CHIA!Q9+ZIPAQUIRA!Q9+TABIO!Q9+TENJO!Q9+SOPO!Q9+GACHANCIPA!Q9+TOCANCIPA!Q9+NEMOCON!Q9+COGUA!Q9 -> 141 | R9: =Q9/E7*100000 -> 29.564521 | S9: =CAJICA!S9+COTA!S10+CHIA!S9+ZIPAQUIRA!S9+TABIO!S9+TENJO!S9+SOPO!S9+GACHANCIPA!S9+TOCANCIPA!S9+NEMOCON!S9+COGUA!S9 -> 133 | T9: =S9/F7*100000 -> 27.042744 | U9: =CAJICA!U9+COTA!U10+CHIA!U9+ZIPAQUIRA!U9+TABIO!U9+TENJO!U9+SOPO!U9+GACHANCIPA!U9+TOCANCIPA!U9+NEMOCON!U9+COGUA!U9 -> 133 | V9: =U9/G7*100000 -> #VALUE! | W9: =CAJICA!W9+COTA!W10+CHIA!W9+ZIPAQUIRA!W9+TABIO!W9+TENJO!W9+SOPO!W9+GACHANCIPA!W9+TOCANCIPA!W9+NEMOCON!W9+COGUA!W9 -> 67 | X9: =W9/H7*100000 -> 12.873376 | Y9: =((M9+O9+Q9+S9)/4) -> 131.75 | Z9: =((N9+P9+R9+T9)/4) -> 28.015687 | AA9: =((S9+U9)/2) -> 133 | AB9: =(V9+X9)/2 -> #VALUE! | AC9: DANE
B10: POBLACION MASCULINA | C10: =CAJICA!C10+COTA!C10+CHIA!C10+ZIPAQUIRA!C10+TABIO!C10+TENJO!C10+SOPO!C10+GACHANCIPA!C10+TOCANCIPA!C10+NEMOCON!C10+COGUA!C10 -> 210175.67 | D10: =CAJICA!D10+COTA!D10+CHIA!D10+ZIPAQUIRA!D10+TABIO!D10+TENJO!D10+SOPO!D10+GACHANCIPA!D10+TOCANCIPA!D10+NEMOCON!D10+COGUA!D10 -> 203482.23 | E10: =CAJICA!E10+COTA!E10+CHIA!E10+ZIPAQUIRA!E10+TABIO!E10+TENJO!E10+SOPO!E10+GACHANCIPA!E10+TOCANCIPA!E10+NEMOCON!E10+COGUA!E10 -> #VALUE! | F10: =CAJICA!F10+COTA!F10+CHIA!F10+ZIPAQUIRA!F10+TABIO!F10+TENJO!F10+SOPO!F10+GACHANCIPA!F10+TOCANCIPA!F10+NEMOCON!F10+COGUA!F10 -> 231756.71 | G10: =CAJICA!G10+COTA!G10+CHIA!G10+ZIPAQUIRA!G10+TABIO!G10+TENJO!G10+SOPO!G10+GACHANCIPA!G10+TOCANCIPA!G10+NEMOCON!G10+COGUA!G10 -> 235655 | H10: =CAJICA!H10+COTA!H10+CHIA!H10+ZIPAQUIRA!H10+TABIO!H10+TENJO!H10+SOPO!H10+GACHANCIPA!H10+TOCANCIPA!H10+NEMOCON!H10+COGUA!H10 -> 242799.26 | L10: TASA DE MORTALIDAD POR IRA < 5 AÑOS | M10: =CAJICA!M10+COTA!M11+CHIA!M10+ZIPAQUIRA!M10+TABIO!M10+TENJO!M10+SOPO!M10+GACHANCIPA!M10+TOCANCIPA!M10+NEMOCON!M10+COGUA!M10 -> 0 | N10: =M10/C15*100000 -> 0 | O10: =CAJICA!O10+COTA!O11+CHIA!O10+ZIPAQUIRA!O10+TABIO!O10+TENJO!O10+SOPO!O10+GACHANCIPA!O10+TOCANCIPA!O10+NEMOCON!O10+COGUA!O10 -> 0 | P10: =O10/D15*100000 -> 0 | Q10: =CAJICA!Q10+COTA!Q11+CHIA!Q10+ZIPAQUIRA!Q10+TABIO!Q10+TENJO!Q10+SOPO!Q10+GACHANCIPA!Q10+TOCANCIPA!Q10+NEMOCON!Q10+COGUA!Q10 -> 1 | R10: =Q10/E15*100000 -> 2.4378792 | S10: =CAJICA!S10+COTA!S11+CHIA!S10+ZIPAQUIRA!S10+TABIO!S10+TENJO!S10+SOPO!S10+GACHANCIPA!S10+TOCANCIPA!S10+NEMOCON!S10+COGUA!S10 -> 0 | T10: =S10/F15*100000 -> 0 | U10: =CAJICA!U10+COTA!U11+CHIA!U10+ZIPAQUIRA!U10+TABIO!U10+TENJO!U10+SOPO!U10+GACHANCIPA!U10+TOCANCIPA!U10+NEMOCON!U10+COGUA!U10 -> 2 | V10: =U10/G15*100000 -> 4.9185652 | W10: =CAJICA!W10+COTA!W11+CHIA!W10+ZIPAQUIRA!W10+TABIO!W10+TENJO!W10+SOPO!W10+GACHANCIPA!W10+TOCANCIPA!W10+NEMOCON!W10+COGUA!W10 -> 2 | X10: =W10/H15*100000 -> 4.9001292 | Y10: =((M10+O10+Q10+S10)/4) -> 0.25 | Z10: =((N10+P10+R10+T10)/4) -> 0.6094698 | AA10: =((S10+U10)/2) -> 1 | AB10: =(V10+X10)/2 -> 4.9093472 | AC10: DANE
B11: POBLACION FEMENINA | C11: =CAJICA!C11+COTA!C11+CHIA!C11+ZIPAQUIRA!C11+TABIO!C11+TENJO!C11+SOPO!C11+GACHANCIPA!C11+TOCANCIPA!C11+NEMOCON!C11+COGUA!C11 -> 221208.7 | D11: =CAJICA!D11+COTA!D11+CHIA!D11+ZIPAQUIRA!D11+TABIO!D11+TENJO!D11+SOPO!D11+GACHANCIPA!D11+TOCANCIPA!D11+NEMOCON!D11+COGUA!D11 -> 214274.79 | E11: =CAJICA!E11+COTA!E11+CHIA!E11+ZIPAQUIRA!E11+TABIO!E11+TENJO!E11+SOPO!E11+GACHANCIPA!E11+TOCANCIPA!E11+NEMOCON!E11+COGUA!E11 -> 236129.38 | F11: =CAJICA!F11+COTA!F11+CHIA!F11+ZIPAQUIRA!F11+TABIO!F11+TENJO!F11+SOPO!F11+GACHANCIPA!F11+TOCANCIPA!F11+NEMOCON!F11+COGUA!F11 -> 242909.66 | G11: =CAJICA!G11+COTA!G11+CHIA!G11+ZIPAQUIRA!G11+TABIO!G11+TENJO!G11+SOPO!G11+GACHANCIPA!G11+TOCANCIPA!G11+NEMOCON!G11+COGUA!G11 -> 248349.94 | H11: =CAJICA!H11+COTA!H11+CHIA!H11+ZIPAQUIRA!H11+TABIO!H11+TENJO!H11+SOPO!H11+GACHANCIPA!H11+TOCANCIPA!H11+NEMOCON!H11+COGUA!H11 -> 255235.18 | L11: TASA DE MORTALIDAD POR EDA < 5 AÑOS | M11: =CAJICA!M11+COTA!M12+CHIA!M11+ZIPAQUIRA!M11+TABIO!M11+TENJO!M11+SOPO!M11+GACHANCIPA!M11+TOCANCIPA!M11+NEMOCON!M11+COGUA!M11 -> 108 | N11: =M11/C15*100000 -> 275.29863 | O11: =CAJICA!O11+COTA!O12+CHIA!O11+ZIPAQUIRA!O11+TABIO!O11+TENJO!O11+SOPO!O11+GACHANCIPA!O11+TOCANCIPA!O11+NEMOCON!O11+COGUA!O11 -> 131 | P11: =O11/D16*100000 -> 37.044999 | Q11: =CAJICA!Q11+COTA!Q12+CHIA!Q11+ZIPAQUIRA!Q11+TABIO!Q11+TENJO!Q11+SOPO!Q11+GACHANCIPA!Q11+TOCANCIPA!Q11+NEMOCON!Q11+COGUA!Q11 -> 201 | R11: =Q11/F16*100000 -> 55.029155 | S11: =CAJICA!S11+COTA!S12+CHIA!S11+ZIPAQUIRA!S11+TABIO!S11+TENJO!S11+SOPO!S11+GACHANCIPA!S11+TOCANCIPA!S11+NEMOCON!S11+COGUA!S11 -> 233 | T11: =S11/F15*100000 -> 572.80103 | U11: =CAJICA!U11+COTA!U12+CHIA!U11+ZIPAQUIRA!U11+TABIO!U11+TENJO!U11+SOPO!U11+GACHANCIPA!U11+TOCANCIPA!U11+NEMOCON!U11+COGUA!U11 -> 320 | V11: =U11/G15*100000 -> 786.97043 | W11: =CAJICA!W11+COTA!W12+CHIA!W11+ZIPAQUIRA!W11+TABIO!W11+TENJO!W11+SOPO!W11+GACHANCIPA!W11+TOCANCIPA!W11+NEMOCON!W11+COGUA!W11 -> 182 | X11: =W11/H15*100000 -> 445.91176 | Y11: =((M11+O11+Q11+S11)/4) -> 168.25 | Z11: =((N11+P11+R11+T11)/4) -> 235.04345 | AA11: =((S11+U11)/2) -> 276.5 | AB11: =(V11+X11)/2 -> 616.44109 | AC11: DANE
B12: NACIMIENTOS | C12: =CAJICA!C12+COTA!C12+CHIA!C12+ZIPAQUIRA!C12+TABIO!C12+TENJO!C12+SOPO!C12+GACHANCIPA!C12+TOCANCIPA!C12+NEMOCON!C12+COGUA!C12 -> 4516 | D12: =CAJICA!D12+COTA!D12+CHIA!D12+ZIPAQUIRA!D12+TABIO!D12+TENJO!D12+SOPO!D12+GACHANCIPA!D12+TOCANCIPA!D12+NEMOCON!D12+COGUA!D12 -> 4944 | E12: =CAJICA!E12+COTA!E12+CHIA!E12+ZIPAQUIRA!E12+TABIO!E12+TENJO!E12+SOPO!E12+GACHANCIPA!E12+TOCANCIPA!E12+NEMOCON!E12+COGUA!E12 -> 5076 | F12: =CAJICA!F12+COTA!F12+CHIA!F12+ZIPAQUIRA!F12+TABIO!F12+TENJO!F12+SOPO!F12+GACHANCIPA!F12+TOCANCIPA!F12+NEMOCON!F12+COGUA!F12 -> 4575 | G12: =CAJICA!G12+COTA!G12+CHIA!G12+ZIPAQUIRA!G12+TABIO!G12+TENJO!G12+SOPO!G12+GACHANCIPA!G12+TOCANCIPA!G12+NEMOCON!G12+COGUA!G12 -> 4645 | H12: =CAJICA!H12+COTA!H12+CHIA!H12+ZIPAQUIRA!H12+TABIO!H12+TENJO!H12+SOPO!H12+GACHANCIPA!H12+TOCANCIPA!H12+NEMOCON!H12+COGUA!H12 -> 1803 | L12: TASA BRUTA DE VIOLENCIA INTRAFAMILIAR | M12: =CAJICA!M12+COTA!M13+CHIA!M12+ZIPAQUIRA!M12+TABIO!M12+TENJO!M12+SOPO!M12+GACHANCIPA!M12+TOCANCIPA!M12+NEMOCON!M12+COGUA!M12 -> 1295 | N12: =M12/C7*100000 -> 289.53623 | O12: =CAJICA!O12+COTA!O13+CHIA!O12+ZIPAQUIRA!O12+TABIO!O12+TENJO!O12+SOPO!O12+GACHANCIPA!O12+TOCANCIPA!O12+NEMOCON!O12+COGUA!O12 -> 1635 | P12: =O12/D7*100000 -> 353.61061 | Q12: =CAJICA!Q12+COTA!Q13+CHIA!Q12+ZIPAQUIRA!Q12+TABIO!Q12+TENJO!Q12+SOPO!Q12+GACHANCIPA!Q12+TOCANCIPA!Q12+NEMOCON!Q12+COGUA!Q12 -> 2540 | R12: =Q12/E7*100000 -> 532.58073 | S12: =CAJICA!S12+COTA!S13+CHIA!S12+ZIPAQUIRA!S12+TABIO!S12+TENJO!S12+SOPO!S12+GACHANCIPA!S12+TOCANCIPA!S12+NEMOCON!S12+COGUA!S12 -> 2889 | T12: =S12/F7*100000 -> 587.41719 | U12: =CAJICA!U12+COTA!U13+CHIA!U12+ZIPAQUIRA!U12+TABIO!U12+TENJO!U12+SOPO!U12+GACHANCIPA!U12+TOCANCIPA!U12+NEMOCON!U12+COGUA!U12 -> 3040 | V12: =U12/G7*100000 -> #VALUE! | W12: =CAJICA!W12+COTA!W13+CHIA!W12+ZIPAQUIRA!W12+TABIO!W12+TENJO!W12+SOPO!W12+GACHANCIPA!W12+TOCANCIPA!W12+NEMOCON!W12+COGUA!W12 -> 1496 | X12: =W12/H7*100000 -> 287.44135 | Y12: =((M12+O12+Q12+S12)/4) -> 2089.75 | Z12: =((N12+P12+R12+T12)/4) -> 440.78619 | AA12: =((S12+U12)/2) -> 2964.5 | AB12: =(V12+X12)/2 -> #VALUE! | AC12: SIVIGILA
B13: DEFUNCIONES | C13: =CAJICA!C13+COTA!C13+CHIA!C13+ZIPAQUIRA!C13+TABIO!C13+TENJO!C13+SOPO!C13+GACHANCIPA!C13+TOCANCIPA!C13+NEMOCON!C13+COGUA!C13 -> 2035 | D13: =CAJICA!D13+COTA!D13+CHIA!D13+ZIPAQUIRA!D13+TABIO!D13+TENJO!D13+SOPO!D13+GACHANCIPA!D13+TOCANCIPA!D13+NEMOCON!D13+COGUA!D13 -> 2851 | E13: =CAJICA!E13+COTA!E13+CHIA!E13+ZIPAQUIRA!E13+TABIO!E13+TENJO!E13+SOPO!E13+GACHANCIPA!E13+TOCANCIPA!E13+NEMOCON!E13+COGUA!E13 -> 2150 | F13: =CAJICA!F13+COTA!F13+CHIA!F13+ZIPAQUIRA!F13+TABIO!F13+TENJO!F13+SOPO!F13+GACHANCIPA!F13+TOCANCIPA!F13+NEMOCON!F13+COGUA!F13 -> 1932 | G13: =CAJICA!G13+COTA!G13+CHIA!G13+ZIPAQUIRA!G13+TABIO!G13+TENJO!G13+SOPO!G13+GACHANCIPA!G13+TOCANCIPA!G13+NEMOCON!G13+COGUA!G13 -> 2081 | H13: =CAJICA!H13+COTA!H13+CHIA!H13+ZIPAQUIRA!H13+TABIO!H13+TENJO!H13+SOPO!H13+GACHANCIPA!H13+TOCANCIPA!H13+NEMOCON!H13+COGUA!H13 -> 960 | L13: TASA DE VIOLENCIA DE GENERO FEMENINA | M13: =CAJICA!M13+COTA!M14+CHIA!M13+ZIPAQUIRA!M13+TABIO!M13+TENJO!M13+SOPO!M13+GACHANCIPA!M13+TOCANCIPA!M13+NEMOCON!M13+COGUA!M13 -> 1002 | N13: =M13/C11*100000 -> 452.9659 | O13: =CAJICA!O13+COTA!O14+CHIA!O13+ZIPAQUIRA!O13+TABIO!O13+TENJO!O13+SOPO!O13+GACHANCIPA!O13+TOCANCIPA!O13+NEMOCON!O13+COGUA!O13 -> 1292 | P13: =O13/D11*100000 -> 602.96407 | Q13: =CAJICA!Q13+COTA!Q14+CHIA!Q13+ZIPAQUIRA!Q13+TABIO!Q13+TENJO!Q13+SOPO!Q13+GACHANCIPA!Q13+TOCANCIPA!Q13+NEMOCON!Q13+COGUA!Q13 -> 1978 | R13: =Q13/E11*100000 -> 837.67636 | S13: =CAJICA!S13+COTA!S14+CHIA!S13+ZIPAQUIRA!S13+TABIO!S13+TENJO!S13+SOPO!S13+GACHANCIPA!S13+TOCANCIPA!S13+NEMOCON!S13+COGUA!S13 -> 2196 | T13: =S13/F11*100000 -> 904.03979 | U13: =CAJICA!U13+COTA!U14+CHIA!U13+ZIPAQUIRA!U13+TABIO!U13+TENJO!U13+SOPO!U13+GACHANCIPA!U13+TOCANCIPA!U13+NEMOCON!U13+COGUA!U13 -> 2282 | V13: =U13/G11*100000 -> 918.86472 | W13: =CAJICA!W13+COTA!W14+CHIA!W13+ZIPAQUIRA!W13+TABIO!W13+TENJO!W13+SOPO!W13+GACHANCIPA!W13+TOCANCIPA!W13+NEMOCON!W13+COGUA!W13 -> 1224 | X13: =W13/H11*100000 -> 479.55771 | Y13: =((M13+O13+Q13+S13)/4) -> 1617 | Z13: =((N13+P13+R13+T13)/4) -> 699.41153 | AA13: =((S13+U13)/2) -> 2239 | AB13: =(V13+X13)/2 -> 699.21121 | AC13: SIVIGILA
B14: POBLACION MENOR 1 AÑO | C14: =CAJICA!C14+COTA!C14+CHIA!C14+ZIPAQUIRA!C14+TABIO!C14+TENJO!C14+SOPO!C14+GACHANCIPA!C14+TOCANCIPA!C14+NEMOCON!C14+COGUA!C14 -> 9214 | D14: =CAJICA!D14+COTA!D14+CHIA!D14+ZIPAQUIRA!D14+TABIO!D14+TENJO!D14+SOPO!D14+GACHANCIPA!D14+TOCANCIPA!D14+NEMOCON!D14+COGUA!D14 -> 9379 | E14: =CAJICA!E14+COTA!E14+CHIA!E14+ZIPAQUIRA!E14+TABIO!E14+TENJO!E14+SOPO!E14+GACHANCIPA!E14+TOCANCIPA!E14+NEMOCON!E14+COGUA!E14 -> 9961 | F14: =CAJICA!F14+COTA!F14+CHIA!F14+ZIPAQUIRA!F14+TABIO!F14+TENJO!F14+SOPO!F14+GACHANCIPA!F14+TOCANCIPA!F14+NEMOCON!F14+COGUA!F14 -> 8501 | G14: =CAJICA!G14+COTA!G14+CHIA!G14+ZIPAQUIRA!G14+TABIO!G14+TENJO!G14+SOPO!G14+GACHANCIPA!G14+TOCANCIPA!G14+NEMOCON!G14+COGUA!G14 -> 9868 | H14: =CAJICA!H14+COTA!H14+CHIA!H14+ZIPAQUIRA!H14+TABIO!H14+TENJO!H14+SOPO!H14+GACHANCIPA!H14+TOCANCIPA!H14+NEMOCON!H14+COGUA!H14 -> 9951 | L14: TASA DE MORTALIDAD INFANTIL | M14: =CAJICA!M14+COTA!M15+CHIA!M14+ZIPAQUIRA!M14+TABIO!M14+TENJO!M14+SOPO!M14+GACHANCIPA!M14+TOCANCIPA!M14+NEMOCON!M14+COGUA!M14 -> 28 | N14: =M14/M4*1000 -> 6.7226891 | O14: =CAJICA!O14+COTA!O15+CHIA!O14+ZIPAQUIRA!O14+TABIO!O14+TENJO!O14+SOPO!O14+GACHANCIPA!O14+TOCANCIPA!O14+NEMOCON!O14+COGUA!O14 -> 24 | P14: =O14/O4*1000 -> 5.197055 | Q14: =CAJICA!Q14+COTA!Q15+CHIA!Q14+ZIPAQUIRA!Q14+TABIO!Q14+TENJO!Q14+SOPO!Q14+GACHANCIPA!Q14+TOCANCIPA!Q14+NEMOCON!Q14+COGUA!Q14 -> 35 | R14: =Q14/Q4*1000 -> 7.3560319 | S14: =CAJICA!S14+COTA!S15+CHIA!S14+ZIPAQUIRA!S14+TABIO!S14+TENJO!S14+SOPO!S14+GACHANCIPA!S14+TOCANCIPA!S14+NEMOCON!S14+COGUA!S14 -> 25 | T14: =S14/S4*1000 -> 5.8754407 | U14: =CAJICA!U14+COTA!U15+CHIA!U14+ZIPAQUIRA!U14+TABIO!U14+TENJO!U14+SOPO!U14+GACHANCIPA!U14+TOCANCIPA!U14+NEMOCON!U14+COGUA!U14 -> 20 | V14: =U14/U4*1000 -> 4.6104195 | W14: =CAJICA!W14+COTA!W15+CHIA!W14+ZIPAQUIRA!W14+TABIO!W14+TENJO!W14+SOPO!W14+GACHANCIPA!W14+TOCANCIPA!W14+NEMOCON!W14+COGUA!W14 -> 18 | X14: =W14/W4*1000 -> 9.7297297 | Y14: =((M14+O14+Q14+S14)/4) -> 28 | Z14: =((N14+P14+R14+T14)/4) -> 6.2878042 | AA14: =((S14+U14)/2) -> 22.5 | AB14: =(V14+X14)/2 -> 7.1700746 | AC14: DANE
B15: POBLACION MENOR 5 AÑOS | C15: =CAJICA!C15+COTA!C15+CHIA!C15+ZIPAQUIRA!C15+TABIO!C15+TENJO!C15+SOPO!C15+GACHANCIPA!C15+TOCANCIPA!C15+NEMOCON!C15+COGUA!C15 -> 39230.126 | D15: =CAJICA!D15+COTA!D15+CHIA!D15+ZIPAQUIRA!D15+TABIO!D15+TENJO!D15+SOPO!D15+GACHANCIPA!D15+TOCANCIPA!D15+NEMOCON!D15+COGUA!D15 -> 40297.206 | E15: =CAJICA!E15+COTA!E15+CHIA!E15+ZIPAQUIRA!E15+TABIO!E15+TENJO!E15+SOPO!E15+GACHANCIPA!E15+TOCANCIPA!E15+NEMOCON!E15+COGUA!E15 -> 41019.26 | F15: =CAJICA!F15+COTA!F15+CHIA!F15+ZIPAQUIRA!F15+TABIO!F15+TENJO!F15+SOPO!F15+GACHANCIPA!F15+TOCANCIPA!F15+NEMOCON!F15+COGUA!F15 -> 40677.301 | G15: =CAJICA!G15+COTA!G15+CHIA!G15+ZIPAQUIRA!G15+TABIO!G15+TENJO!G15+SOPO!G15+GACHANCIPA!G15+TOCANCIPA!G15+NEMOCON!G15+COGUA!G15 -> 40662.265 | H15: =CAJICA!H15+COTA!H15+CHIA!H15+ZIPAQUIRA!H15+TABIO!H15+TENJO!H15+SOPO!H15+GACHANCIPA!H15+TOCANCIPA!H15+NEMOCON!H15+COGUA!H15 -> 40815.25 | L15: TASA DE MORTALIDAD INFANTIL < 5 AÑOS | M15: =CAJICA!M15+COTA!M16+CHIA!M15+ZIPAQUIRA!M15+TABIO!M15+TENJO!M15+SOPO!M15+GACHANCIPA!M15+TOCANCIPA!M15+NEMOCON!M15+COGUA!M15 -> 75 | N15: =M15/C15*100000 -> 191.17961 | O15: =CAJICA!O15+COTA!O16+CHIA!O15+ZIPAQUIRA!O15+TABIO!O15+TENJO!O15+SOPO!O15+GACHANCIPA!O15+TOCANCIPA!O15+NEMOCON!O15+COGUA!O15 -> 59 | P15: =O15/D15*100000 -> 146.41214 | Q15: =CAJICA!Q15+COTA!Q16+CHIA!Q15+ZIPAQUIRA!Q15+TABIO!Q15+TENJO!Q15+SOPO!Q15+GACHANCIPA!Q15+TOCANCIPA!Q15+NEMOCON!Q15+COGUA!Q15 -> 67 | R15: =Q15/E15*100000 -> 163.33791 | S15: =CAJICA!S15+COTA!S16+CHIA!S15+ZIPAQUIRA!S15+TABIO!S15+TENJO!S15+SOPO!S15+GACHANCIPA!S15+TOCANCIPA!S15+NEMOCON!S15+COGUA!S15 -> 64 | T15: =S15/F15*100000 -> 157.33591 | U15: =CAJICA!U15+COTA!U16+CHIA!U15+ZIPAQUIRA!U15+TABIO!U15+TENJO!U15+SOPO!U15+GACHANCIPA!U15+TOCANCIPA!U15+NEMOCON!U15+COGUA!U15 -> 61 | V15: =U15/G15*100000 -> 150.01624 | W15: =CAJICA!W15+COTA!W16+CHIA!W15+ZIPAQUIRA!W15+TABIO!W15+TENJO!W15+SOPO!W15+GACHANCIPA!W15+TOCANCIPA!W15+NEMOCON!W15+COGUA!W15 -> 28 | X15: =W15/H15*100000 -> 68.601809 | Y15: =((M15+O15+Q15+S15)/4) -> 66.25 | Z15: =((N15+P15+R15+T15)/4) -> 164.56639 | AA15: =((S15+U15)/2) -> 62.5 | AB15: =(V15+X15)/2 -> 109.30902 | AC15: DANE
B16: POBLACION MAYOR 15 AÑOS | C16: =CAJICA!C16+COTA!C16+CHIA!C16+ZIPAQUIRA!C16+TABIO!C16+TENJO!C16+SOPO!C16+GACHANCIPA!C16+TOCANCIPA!C16+NEMOCON!C16+COGUA!C16 -> 334538.39 | D16: =CAJICA!D16+COTA!D16+CHIA!D16+ZIPAQUIRA!D16+TABIO!D16+TENJO!D16+SOPO!D16+GACHANCIPA!D16+TOCANCIPA!D16+NEMOCON!D16+COGUA!D16 -> 353623.98 | E16: =CAJICA!E16+COTA!E16+CHIA!E16+ZIPAQUIRA!E16+TABIO!E16+TENJO!E16+SOPO!E16+GACHANCIPA!E16+TOCANCIPA!E16+NEMOCON!E16+COGUA!E16 -> 355547.47 | F16: =CAJICA!F16+COTA!F16+CHIA!F16+ZIPAQUIRA!F16+TABIO!F16+TENJO!F16+SOPO!F16+GACHANCIPA!F16+TOCANCIPA!F16+NEMOCON!F16+COGUA!F16 -> 365260.93 | G16: =CAJICA!G16+COTA!G16+CHIA!G16+ZIPAQUIRA!G16+TABIO!G16+TENJO!G16+SOPO!G16+GACHANCIPA!G16+TOCANCIPA!G16+NEMOCON!G16+COGUA!G16 -> 376078.46 | H16: =CAJICA!H16+COTA!H16+CHIA!H16+ZIPAQUIRA!H16+TABIO!H16+TENJO!H16+SOPO!H16+GACHANCIPA!H16+TOCANCIPA!H16+NEMOCON!H16+COGUA!H16 -> 387730.91 | L16: PROPORCION DE BAJO PESO AL NACER | M16: =CAJICA!M16+COTA!M17+CHIA!M16+ZIPAQUIRA!M16+TABIO!M16+TENJO!M16+SOPO!M16+GACHANCIPA!M16+TOCANCIPA!M16+NEMOCON!M16+COGUA!M16 -> 538 | N16: =M16/M4*100 -> 12.917167 | O16: =CAJICA!O16+COTA!O17+CHIA!O16+ZIPAQUIRA!O16+TABIO!O16+TENJO!O16+SOPO!O16+GACHANCIPA!O16+TOCANCIPA!O16+NEMOCON!O16+COGUA!O16 -> 612 | P16: =O16/O4*100 -> 13.25249 | Q16: =CAJICA!Q16+COTA!Q17+CHIA!Q16+ZIPAQUIRA!Q16+TABIO!Q16+TENJO!Q16+SOPO!Q16+GACHANCIPA!Q16+TOCANCIPA!Q16+NEMOCON!Q16+COGUA!Q16 -> 555 | R16: =Q16/Q4*100 -> 11.664565 | S16: =CAJICA!S16+COTA!S17+CHIA!S16+ZIPAQUIRA!S16+TABIO!S16+TENJO!S16+SOPO!S16+GACHANCIPA!S16+TOCANCIPA!S16+NEMOCON!S16+COGUA!S16 -> 491 | T16: =S16/S4*100 -> 11.539365 | U16: =CAJICA!U16+COTA!U17+CHIA!U16+ZIPAQUIRA!U16+TABIO!U16+TENJO!U16+SOPO!U16+GACHANCIPA!U16+TOCANCIPA!U16+NEMOCON!U16+COGUA!U16 -> 505 | V16: =U16/U4*100 -> 11.641309 | W16: =CAJICA!W16+COTA!W17+CHIA!W16+ZIPAQUIRA!W16+TABIO!W16+TENJO!W16+SOPO!W16+GACHANCIPA!W16+TOCANCIPA!W16+NEMOCON!W16+COGUA!W16 -> 219 | X16: =W16/W4*100 -> 11.837838 | Y16: =((M16+O16+Q16+S16)/4) -> 549 | Z16: =((N16+P16+R16+T16)/4) -> 12.343397 | AA16: =((S16+U16)/2) -> 498 | AB16: =(V16+X16)/2 -> 11.739574 | AC16: RUAF
B17: POBLACION MENOR 19 AÑOS | C17: =CAJICA!C17+COTA!C17+CHIA!C17+ZIPAQUIRA!C17+TABIO!C17+TENJO!C17+SOPO!C17+GACHANCIPA!C17+TOCANCIPA!C17+NEMOCON!C17+COGUA!C17 -> 130487.66 | D17: =CAJICA!D17+COTA!D17+CHIA!D17+ZIPAQUIRA!D17+TABIO!D17+TENJO!D17+SOPO!D17+GACHANCIPA!D17+TOCANCIPA!D17+NEMOCON!D17+COGUA!D17 -> 133120.87 | E17: =CAJICA!E17+COTA!E17+CHIA!E17+ZIPAQUIRA!E17+TABIO!E17+TENJO!E17+SOPO!E17+GACHANCIPA!E17+TOCANCIPA!E17+NEMOCON!E17+COGUA!E17 -> 136414.02 | F17: =CAJICA!F17+COTA!F17+CHIA!F17+ZIPAQUIRA!F17+TABIO!F17+TENJO!F17+SOPO!F17+GACHANCIPA!F17+TOCANCIPA!F17+NEMOCON!F17+COGUA!F17 -> 138792.17 | G17: =CAJICA!G17+COTA!G17+CHIA!G17+ZIPAQUIRA!G17+TABIO!G17+TENJO!G17+SOPO!G17+GACHANCIPA!G17+TOCANCIPA!G17+NEMOCON!G17+COGUA!G17 -> 137852.27 | H17: =CAJICA!H17+COTA!H17+CHIA!H17+ZIPAQUIRA!H17+TABIO!H17+TENJO!H17+SOPO!H17+GACHANCIPA!H17+TOCANCIPA!H17+NEMOCON!H17+COGUA!H17 -> 139951.33 | L17: PROPORCION DE BAJO PESO AL NACER A TERMINO | M17: =CAJICA!M17+COTA!M18+CHIA!M17+ZIPAQUIRA!M17+TABIO!M17+TENJO!M17+SOPO!M17+GACHANCIPA!M17+TOCANCIPA!M17+NEMOCON!M17+COGUA!M17 -> 199 | N17: =M17/M4*100 -> 4.7779112 | O17: =CAJICA!O17+COTA!O18+CHIA!O17+ZIPAQUIRA!O17+TABIO!O17+TENJO!O17+SOPO!O17+GACHANCIPA!O17+TOCANCIPA!O17+NEMOCON!O17+COGUA!O17 -> 240 | P17: =O17/O4*100 -> 5.197055 | Q17: =CAJICA!Q17+COTA!Q18+CHIA!Q17+ZIPAQUIRA!Q17+TABIO!Q17+TENJO!Q17+SOPO!Q17+GACHANCIPA!Q17+TOCANCIPA!Q17+NEMOCON!Q17+COGUA!Q17 -> 237 | R17: =Q17/Q4*100 -> 4.9810845 | S17: =CAJICA!S17+COTA!S18+CHIA!S17+ZIPAQUIRA!S17+TABIO!S17+TENJO!S17+SOPO!S17+GACHANCIPA!S17+TOCANCIPA!S17+NEMOCON!S17+COGUA!S17 -> 220 | T17: =S17/S4*100 -> 5.1703878 | U17: =CAJICA!U17+COTA!U18+CHIA!U17+ZIPAQUIRA!U17+TABIO!U17+TENJO!U17+SOPO!U17+GACHANCIPA!U17+TOCANCIPA!U17+NEMOCON!U17+COGUA!U17 -> 258 | V17: =U17/U4*100 -> 5.9474412 | W17: =CAJICA!W17+COTA!W18+CHIA!W17+ZIPAQUIRA!W17+TABIO!W17+TENJO!W17+SOPO!W17+GACHANCIPA!W17+TOCANCIPA!W17+NEMOCON!W17+COGUA!W17 -> 103 | X17: =W17/W4*100 -> 5.5675676 | Y17: =((M17+O17+Q17+S17)/4) -> 224 | Z17: =((N17+P17+R17+T17)/4) -> 5.0316096 | AA17: =((S17+U17)/2) -> 239 | AB17: =(V17+X17)/2 -> 5.7575044 | AC17: RUAF
B18: POBLACION MENOR 65 AÑOS | C18: =CAJICA!C18+COTA!C18+CHIA!C18+ZIPAQUIRA!C18+TABIO!C18+TENJO!C18+SOPO!C18+GACHANCIPA!C18+TOCANCIPA!C18+NEMOCON!C18+COGUA!C18 -> 396368.5 | D18: =CAJICA!D18+COTA!D18+CHIA!D18+ZIPAQUIRA!D18+TABIO!D18+TENJO!D18+SOPO!D18+GACHANCIPA!D18+TOCANCIPA!D18+NEMOCON!D18+COGUA!D18 -> 417996.23 | E18: =CAJICA!E18+COTA!E18+CHIA!E18+ZIPAQUIRA!E18+TABIO!E18+TENJO!E18+SOPO!E18+GACHANCIPA!E18+TOCANCIPA!E18+NEMOCON!E18+COGUA!E18 -> 420203.81 | F18: =CAJICA!F18+COTA!F18+CHIA!F18+ZIPAQUIRA!F18+TABIO!F18+TENJO!F18+SOPO!F18+GACHANCIPA!F18+TOCANCIPA!F18+NEMOCON!F18+COGUA!F18 -> 432202.35 | G18: =CAJICA!G18+COTA!G18+CHIA!G18+ZIPAQUIRA!G18+TABIO!G18+TENJO!G18+SOPO!G18+GACHANCIPA!G18+TOCANCIPA!G18+NEMOCON!G18+COGUA!G18 -> 441767.89 | H18: =CAJICA!H18+COTA!H18+CHIA!H18+ZIPAQUIRA!H18+TABIO!H18+TENJO!H18+SOPO!H18+GACHANCIPA!H18+TOCANCIPA!H18+NEMOCON!H18+COGUA!H18 -> 451382.35 | L18: TASA DE DESNUTRICION AGUDA < 5 AÑOS | M18: =CAJICA!M18+COTA!M19+CHIA!M18+ZIPAQUIRA!M18+TABIO!M18+TENJO!M18+SOPO!M18+GACHANCIPA!M18+TOCANCIPA!M18+NEMOCON!M18+COGUA!M18 -> 117 | N18: =M18/C15*1000 -> 2.9824018 | O18: =CAJICA!O18+COTA!O19+CHIA!O18+ZIPAQUIRA!O18+TABIO!O18+TENJO!O18+SOPO!O18+GACHANCIPA!O18+TOCANCIPA!O18+NEMOCON!O18+COGUA!O18 -> 112 | P18: =O18/D15*1000 -> 2.779349 | Q18: =CAJICA!Q18+COTA!Q19+CHIA!Q18+ZIPAQUIRA!Q18+TABIO!Q18+TENJO!Q18+SOPO!Q18+GACHANCIPA!Q18+TOCANCIPA!Q18+NEMOCON!Q18+COGUA!Q18 -> 213 | R18: =Q18/E15*1000 -> 5.1926827 | S18: =CAJICA!S18+COTA!S19+CHIA!S18+ZIPAQUIRA!S18+TABIO!S18+TENJO!S18+SOPO!S18+GACHANCIPA!S18+TOCANCIPA!S18+NEMOCON!S18+COGUA!S18 -> 152 | T18: =S18/F15*1000 -> 3.7367278 | U18: =CAJICA!U18+COTA!U19+CHIA!U18+ZIPAQUIRA!U18+TABIO!U18+TENJO!U18+SOPO!U18+GACHANCIPA!U18+TOCANCIPA!U18+NEMOCON!U18+COGUA!U18 -> 257 | V18: =U18/G15*1000 -> 6.3203562 | W18: =CAJICA!W18+COTA!W19+CHIA!W18+ZIPAQUIRA!W18+TABIO!W18+TENJO!W18+SOPO!W18+GACHANCIPA!W18+TOCANCIPA!W18+NEMOCON!W18+COGUA!W18 -> 114 | X18: =W18/H15*1000 -> 2.7930737 | Y18: =((M18+O18+Q18+S18)/4) -> 148.5 | Z18: =((N18+P18+R18+T18)/4) -> 3.6727903 | AA18: =((S18+U18)/2) -> 204.5 | AB18: =(V18+X18)/2 -> 4.5567149 | AC18: SIVIGILA
B19: POBLACION 20 A 65 | C19: =CAJICA!C19+COTA!C19+CHIA!C19+ZIPAQUIRA!C19+TABIO!C19+TENJO!C19+SOPO!C19+GACHANCIPA!C19+TOCANCIPA!A19+NEMOCON!C19+COGUA!C19 -> 241819.84 | D19: =CAJICA!D19+COTA!D19+CHIA!D19+ZIPAQUIRA!D19+TABIO!D19+TENJO!D19+SOPO!D19+GACHANCIPA!D19+TOCANCIPA!D19+NEMOCON!D19+COGUA!D19 -> 289157.36 | E19: =CAJICA!E19+COTA!E19+CHIA!E19+ZIPAQUIRA!E19+TABIO!E19+TENJO!E19+SOPO!E19+GACHANCIPA!E19+TOCANCIPA!E19+NEMOCON!E19+COGUA!E19 -> 289131.79 | F19: =CAJICA!F19+COTA!F19+CHIA!F19+ZIPAQUIRA!F19+TABIO!F19+TENJO!F19+SOPO!F19+GACHANCIPA!F19+TOCANCIPA!F19+NEMOCON!F19+COGUA!F19 -> 297566.18 | G19: =CAJICA!G19+COTA!G19+CHIA!G19+ZIPAQUIRA!G19+TABIO!G19+TENJO!G19+SOPO!G19+GACHANCIPA!G19+TOCANCIPA!G19+NEMOCON!G19+COGUA!G19 -> 309578.62 | H19: =CAJICA!H19+COTA!H19+CHIA!H19+ZIPAQUIRA!H19+TABIO!H19+TENJO!H19+SOPO!H19+GACHANCIPA!H19+TOCANCIPA!H19+NEMOCON!H19+COGUA!H19 -> 316219.02 | L19: PROPORCION DE EMBARAZO EN ADOLESCENTE | M19: =CAJICA!M19+COTA!M20+CHIA!M19+ZIPAQUIRA!M19+TABIO!M19+TENJO!M19+SOPO!M19+GACHANCIPA!M19+TOCANCIPA!M19+NEMOCON!M19+COGUA!M19 -> 387 | N19: =M19/M4*100 -> 9.2917167 | O19: =CAJICA!O19+COTA!O20+CHIA!O19+ZIPAQUIRA!O19+TABIO!O19+TENJO!O19+SOPO!O19+GACHANCIPA!O19+TOCANCIPA!O19+NEMOCON!O19+COGUA!O19 -> 304 | P19: =O19/O4*100 -> 6.5829363 | Q19: =CAJICA!Q19+COTA!Q20+CHIA!Q19+ZIPAQUIRA!Q19+TABIO!Q19+TENJO!Q19+SOPO!Q19+GACHANCIPA!Q19+TOCANCIPA!Q19+NEMOCON!Q19+COGUA!Q19 -> 329 | R19: =Q19/Q4*100 -> 6.91467 | S19: =CAJICA!S19+COTA!S20+CHIA!S19+ZIPAQUIRA!S19+TABIO!S19+TENJO!S19+SOPO!S19+GACHANCIPA!S19+TOCANCIPA!S19+NEMOCON!S19+COGUA!S19 -> 271 | T19: =S19/S4*100 -> 6.3689777 | U19: =CAJICA!U19+COTA!U20+CHIA!U19+ZIPAQUIRA!U19+TABIO!U19+TENJO!U19+SOPO!U19+GACHANCIPA!U19+TOCANCIPA!U19+NEMOCON!U19+COGUA!U19 -> 232 | V19: =U19/U4*100 -> 5.3480867 | W19: =CAJICA!W19+COTA!W20+CHIA!W19+ZIPAQUIRA!W19+TABIO!W19+TENJO!W19+SOPO!W19+GACHANCIPA!W19+TOCANCIPA!W19+NEMOCON!W19+COGUA!W19 -> 105 | X19: =W19/W4*100 -> 5.6756757 | Y19: =((M19+O19+Q19+S19)/4) -> 322.75 | Z19: =((N19+P19+R19+T19)/4) -> 7.2895752 | AA19: =((S19+U19)/2) -> 251.5 | AB19: =(V19+X19)/2 -> 5.5118812 | AC19: RUAF
B20: POBLACION MUJERES 10 A 14 | C20: =CAJICA!C20+COTA!C20+CHIA!C20+ZIPAQUIRA!C20+TABIO!C20+TENJO!C20+SOPO!C20+GACHANCIPA!C20+TOCANCIPA!C20+NEMOCON!C20+COGUA!C20 -> 16450 | D20: =CAJICA!D20+COTA!D20+CHIA!D20+ZIPAQUIRA!D20+TABIO!D20+TENJO!D20+SOPO!D20+GACHANCIPA!D20+TOCANCIPA!D20+NEMOCON!D20+COGUA!D20 -> 18550 | E20: =CAJICA!E20+COTA!E20+CHIA!E20+ZIPAQUIRA!E20+TABIO!E20+TENJO!E20+SOPO!E20+GACHANCIPA!E20+TOCANCIPA!E20+NEMOCON!E20+COGUA!E20 -> 18929 | F20: =CAJICA!F20+COTA!F20+CHIA!F20+ZIPAQUIRA!F20+TABIO!F20+TENJO!F20+SOPO!F20+GACHANCIPA!F20+TOCANCIPA!F20+NEMOCON!F20+COGUA!F20 -> 19365 | G20: =CAJICA!G20+COTA!G20+CHIA!G20+ZIPAQUIRA!G20+TABIO!G20+TENJO!G20+SOPO!G20+GACHANCIPA!G20+TOCANCIPA!G20+NEMOCON!G20+COGUA!G20 -> 19610 | H20: =CAJICA!H20+COTA!H20+CHIA!H20+ZIPAQUIRA!H20+TABIO!H20+TENJO!H20+SOPO!H20+GACHANCIPA!H20+TOCANCIPA!H20+NEMOCON!H20+COGUA!H20 -> 20142 | L20: TASA DE FECUNDIDAD 10 A 14 AÑOS | M20: =CAJICA!M20+COTA!M21+CHIA!M20+ZIPAQUIRA!M20+TABIO!M20+TENJO!M20+SOPO!M20+GACHANCIPA!M20+TOCANCIPA!M20+NEMOCON!M20+COGUA!M20 -> 62 | N20: =M20/C20*1000 -> 3.768997 | O20: =CAJICA!O20+COTA!O21+CHIA!O20+ZIPAQUIRA!O20+TABIO!O20+TENJO!O20+SOPO!O20+GACHANCIPA!O20+TOCANCIPA!O20+NEMOCON!O20+COGUA!O20 -> 42 | P20: =O20/D20*1000 -> 2.2641509 | Q20: =CAJICA!Q20+COTA!Q21+CHIA!Q20+ZIPAQUIRA!Q20+TABIO!Q20+TENJO!Q20+SOPO!Q20+GACHANCIPA!Q20+TOCANCIPA!Q20+NEMOCON!Q20+COGUA!Q20 -> 48 | R20: =Q20/E20*1000 -> 2.5357916 | S20: =CAJICA!S20+COTA!S21+CHIA!S20+ZIPAQUIRA!S20+TABIO!S20+TENJO!S20+SOPO!S20+GACHANCIPA!S20+TOCANCIPA!S20+NEMOCON!S20+COGUA!S20 -> 26 | T20: =S20/F20*1000 -> 1.3426285 | U20: =CAJICA!U20+COTA!U21+CHIA!U20+ZIPAQUIRA!U20+TABIO!U20+TENJO!U20+SOPO!U20+GACHANCIPA!U20+TOCANCIPA!U20+NEMOCON!U20+COGUA!U20 -> 32 | V20: =U20/G20*1000 -> 1.6318205 | W20: =CAJICA!W20+COTA!W21+CHIA!W20+ZIPAQUIRA!W20+TABIO!W20+TENJO!W20+SOPO!W20+GACHANCIPA!W20+TOCANCIPA!W20+NEMOCON!W20+COGUA!W20 -> 16 | X20: =W20/H20*1000 -> 0.79436004 | Y20: =((M20+O20+Q20+S20)/4) -> 44.5 | Z20: =((N20+P20+R20+T20)/4) -> 2.477892 | AA20: =((S20+U20)/2) -> 29 | AB20: =(V20+X20)/2 -> 1.2130903 | AC20: RUAF
B21: POBLACION MUJERES 15 A 19 | C21: =CAJICA!C21+COTA!C21+CHIA!C21+ZIPAQUIRA!C21+TABIO!C21+TENJO!C21+SOPO!C21+GACHANCIPA!C21+TOCANCIPA!C21+NEMOCON!C21+COGUA!C21 -> 18105 | D21: =CAJICA!D21+COTA!D21+CHIA!D21+ZIPAQUIRA!D21+TABIO!D21+TENJO!D21+SOPO!D21+GACHANCIPA!D21+TOCANCIPA!D21+NEMOCON!D21+COGUA!D21 -> 20077 | E21: =CAJICA!E21+COTA!E21+CHIA!E21+ZIPAQUIRA!E21+TABIO!E21+TENJO!E21+SOPO!E21+GACHANCIPA!E21+TOCANCIPA!D21+NEMOCON!E21+COGUA!E21 -> 20162 | F21: =CAJICA!F21+COTA!F21+CHIA!F21+ZIPAQUIRA!F21+TABIO!F21+TENJO!F21+SOPO!F21+GACHANCIPA!F21+TOCANCIPA!F21+NEMOCON!F21+COGUA!F21 -> 20322 | G21: =CAJICA!G21+COTA!G21+CHIA!G21+ZIPAQUIRA!G21+TABIO!G21+TENJO!G21+SOPO!G21+GACHANCIPA!G21+TOCANCIPA!G21+NEMOCON!G21+COGUA!G21 -> 20262 | H21: =CAJICA!H21+COTA!H21+CHIA!H21+ZIPAQUIRA!H21+TABIO!H21+TENJO!H21+SOPO!H21+GACHANCIPA!H21+TOCANCIPA!H21+NEMOCON!H21+COGUA!H21 -> 21255 | L21: TASA DE FECUNDIDAD 15 A 19 AÑOS | M21: =CAJICA!M21+COTA!M22+CHIA!M21+ZIPAQUIRA!M21+TABIO!M21+TENJO!M21+SOPO!M21+GACHANCIPA!M21+TOCANCIPA!M21+NEMOCON!M21+COGUA!M21 -> 527 | N21: =M21/C21*1000 -> 29.107981 | O21: =CAJICA!O21+COTA!O22+CHIA!O21+ZIPAQUIRA!O21+TABIO!O21+TENJO!O21+SOPO!O21+GACHANCIPA!O21+TOCANCIPA!O21+NEMOCON!O21+COGUA!O21 -> 420 | P21: =O21/D21*1000 -> 20.91946 | Q21: =CAJICA!Q21+COTA!Q22+CHIA!Q21+ZIPAQUIRA!Q21+TABIO!Q21+TENJO!Q21+SOPO!Q21+GACHANCIPA!Q21+TOCANCIPA!Q21+NEMOCON!Q21+COGUA!Q21 -> 508 | R21: =Q21/E21*1000 -> 25.195913 | S21: =CAJICA!S21+COTA!S22+CHIA!S21+ZIPAQUIRA!S21+TABIO!S21+TENJO!S21+SOPO!S21+GACHANCIPA!S21+TOCANCIPA!S21+NEMOCON!S21+COGUA!S21 -> 449 | T21: =S21/F21*1000 -> 22.094282 | U21: =CAJICA!U21+COTA!U22+CHIA!U21+ZIPAQUIRA!U21+TABIO!U21+TENJO!U21+SOPO!U21+GACHANCIPA!U21+TOCANCIPA!U21+NEMOCON!U21+COGUA!U21 -> 395 | V21: =U21/G21*1000 -> 19.49462 | W21: =CAJICA!W21+COTA!W22+CHIA!W21+ZIPAQUIRA!W21+TABIO!W21+TENJO!W21+SOPO!W21+GACHANCIPA!W21+TOCANCIPA!W21+NEMOCON!W21+COGUA!W21 -> 202 | X21: =W21/H21*1000 -> 9.5036462 | Y21: =((M21+O21+Q21+S21)/4) -> 476 | Z21: =((N21+P21+R21+T21)/4) -> 24.329409 | AA21: =((S21+U21)/2) -> 422 | AB21: =(V21+X21)/2 -> 14.499133 | AC21: RUAF
B22: POBLACION MUJERES EN EDAD FERTIL | C22: =CAJICA!C22+COTA!C22+CHIA!C22+ZIPAQUIRA!C22+TABIO!C22+TENJO!C22+SOPO!C22+GACHANCIPA!C22+TOCANCIPA!C22+NEMOCON!C22+COGUA!C22 -> 139579.34 | D22: =CAJICA!D22+COTA!D22+CHIA!D22+ZIPAQUIRA!D22+TABIO!D22+TENJO!D22+SOPO!D22+GACHANCIPA!D22+TOCANCIPA!D22+NEMOCON!D22+COGUA!D22 -> 144067.58 | E22: =CAJICA!E22+COTA!E22+CHIA!E22+ZIPAQUIRA!E22+TABIO!E22+TENJO!E22+SOPO!E22+GACHANCIPA!E22+TOCANCIPA!E22+NEMOCON!E22+COGUA!E22 -> 148172.76 | F22: =CAJICA!F22+COTA!F22+CHIA!F22+ZIPAQUIRA!F22+TABIO!F22+TENJO!F22+SOPO!F22+GACHANCIPA!F22+TOCANCIPA!F22+NEMOCON!F22+COGUA!F22 -> 152204.93 | G22: =CAJICA!G22+COTA!G22+CHIA!G22+ZIPAQUIRA!G22+TABIO!G22+TENJO!G22+SOPO!G22+GACHANCIPA!G22+TOCANCIPA!G22+NEMOCON!G22+COGUA!G22 -> 155236.13 | H22: =CAJICA!H22+COTA!H22+CHIA!H22+ZIPAQUIRA!H22+TABIO!H22+TENJO!H22+SOPO!H22+GACHANCIPA!H22+TOCANCIPA!H22+NEMOCON!H22+COGUA!H22 -> 159118.3 | L22: TASA DE MORTALIDAD POR ACCIDENTE DE TRANSITO | M22: =CAJICA!M22+COTA!M23+CHIA!M22+ZIPAQUIRA!M22+TABIO!M22+TENJO!M22+SOPO!M22+GACHANCIPA!M22+TOCANCIPA!M22+NEMOCON!M22+COGUA!M22 -> 39 | N22: =M22/C7*100000 -> 8.7196238 | O22: =CAJICA!O22+COTA!O23+CHIA!O22+ZIPAQUIRA!O22+TABIO!O22+TENJO!O22+SOPO!O22+GACHANCIPA!O22+TOCANCIPA!O22+NEMOCON!O22+COGUA!O22 -> 60 | P22: =O22/D7*100000 -> 12.976536 | Q22: =CAJICA!Q22+COTA!Q23+CHIA!Q22+ZIPAQUIRA!Q22+TABIO!Q22+TENJO!Q22+SOPO!Q22+GACHANCIPA!Q22+TOCANCIPA!Q22+NEMOCON!Q22+COGUA!Q22 -> 56 | R22: =Q22/E7*100000 -> 11.741937 | S22: =CAJICA!S22+COTA!S23+CHIA!S22+ZIPAQUIRA!S22+TABIO!S22+TENJO!S22+SOPO!S22+GACHANCIPA!S22+TOCANCIPA!S22+NEMOCON!S22+COGUA!S22 -> 65 | T22: =S22/F7*100000 -> 13.216379 | U22: =CAJICA!U22+COTA!U23+CHIA!U22+ZIPAQUIRA!U22+TABIO!U22+TENJO!U22+SOPO!U22+GACHANCIPA!U22+TOCANCIPA!U22+NEMOCON!U22+COGUA!U22 -> 64 | V22: =U22/G7*100000 -> #VALUE! | W22: =CAJICA!W22+COTA!W23+CHIA!W22+ZIPAQUIRA!W22+TABIO!W22+TENJO!W22+SOPO!W22+GACHANCIPA!W22+TOCANCIPA!W22+NEMOCON!W22+COGUA!W22 -> 35 | X22: =W22/H7*100000 -> 6.7248979 | Y22: =((M22+O22+Q22+S22)/4) -> 55 | Z22: =((N22+P22+R22+T22)/4) -> 11.663619 | AA22: =((S22+U22)/2) -> 64.5 | AB22: =(V22+X22)/2 -> #VALUE! | AC22: DANE
B23: POBLACION 0 A 5 AÑOS | C23: =CAJICA!C23+COTA!C23+CHIA!C23+ZIPAQUIRA!C23+TABIO!C23+TENJO!C23+SOPO!C23+GACHANCIPA!C23+TOCANCIPA!C23+NEMOCON!C23+COGUA!C23 -> 34871.126 | D23: =CAJICA!D23+COTA!D23+CHIA!D23+ZIPAQUIRA!D23+TABIO!D23+TENJO!D23+SOPO!D23+GACHANCIPA!D23+TOCANCIPA!D23+NEMOCON!D23+COGUA!D23 -> 44718.206 | E23: =CAJICA!E23+COTA!E23+CHIA!E23+ZIPAQUIRA!E23+TABIO!E23+TENJO!E23+SOPO!E23+GACHANCIPA!E23+TOCANCIPA!E23+NEMOCON!E23+COGUA!E23 -> 45489.26 | F23: =CAJICA!F23+COTA!F23+CHIA!F23+ZIPAQUIRA!F23+TABIO!F23+TENJO!F23+SOPO!F23+GACHANCIPA!F23+TOCANCIPA!F23+NEMOCON!F23+COGUA!F23 -> 45159.301 | G23: =CAJICA!G23+COTA!G23+CHIA!G23+ZIPAQUIRA!G23+TABIO!G23+TENJO!G23+SOPO!G23+GACHANCIPA!G23+TOCANCIPA!G23+NEMOCON!G23+COGUA!G23 -> 45196.265 | H23: =CAJICA!H23+COTA!H23+CHIA!H23+ZIPAQUIRA!H23+TABIO!H23+TENJO!H23+SOPO!H23+GACHANCIPA!H23+TOCANCIPA!H23+NEMOCON!H23+COGUA!H23 -> 45366.25 | L23: TASA DE MORTALIDAD POR SUICIDIO | M23: =CAJICA!M23+COTA!M24+CHIA!M23+ZIPAQUIRA!M23+TABIO!M23+TENJO!M23+SOPO!M23+GACHANCIPA!M23+TOCANCIPA!M23+NEMOCON!M23+COGUA!M23 -> 16 | N23: =M23/C7*100000 -> 3.5772816 | O23: =CAJICA!O23+COTA!O24+CHIA!O23+ZIPAQUIRA!O23+TABIO!O23+TENJO!O23+SOPO!O23+GACHANCIPA!O23+TOCANCIPA!O23+NEMOCON!O23+COGUA!O23 -> 27 | P23: =O23/D7*100000 -> 5.8394413 | Q23: =CAJICA!Q23+COTA!Q24+CHIA!Q23+ZIPAQUIRA!Q23+TABIO!Q23+TENJO!Q23+SOPO!Q23+GACHANCIPA!Q23+TOCANCIPA!Q23+NEMOCON!Q23+COGUA!Q23 -> 16 | R23: =Q23/E7*100000 -> 3.3548393 | S23: =CAJICA!S23+COTA!S24+CHIA!S23+ZIPAQUIRA!S23+TABIO!S23+TENJO!S23+SOPO!S23+GACHANCIPA!S23+TOCANCIPA!S23+NEMOCON!S23+COGUA!S23 -> 17 | T23: =S23/F7*100000 -> 3.4565913 | U23: =CAJICA!U23+COTA!U24+CHIA!U23+ZIPAQUIRA!U23+TABIO!U23+TENJO!U23+SOPO!U23+GACHANCIPA!U23+TOCANCIPA!U23+NEMOCON!U23+COGUA!U23 -> 18 | V23: =U23/G7*100000 -> #VALUE! | W23: =CAJICA!W23+COTA!W24+CHIA!W23+ZIPAQUIRA!W23+TABIO!W23+TENJO!W23+SOPO!W23+GACHANCIPA!W23+TOCANCIPA!W23+NEMOCON!W23+COGUA!W23 -> 14 | X23: =W23/H7*100000 -> 2.6899592 | Y23: =((M23+O23+Q23+S23)/4) -> 19 | Z23: =((N23+P23+R23+T23)/4) -> 4.0570384 | AA23: =((S23+U23)/2) -> 17.5 | AB23: =(V23+X23)/2 -> #VALUE! | AC23: DANE
B24: POBLACION 6 A 11 AÑOS | C24: =CAJICA!C24+COTA!C24+CHIA!C24+ZIPAQUIRA!C24+TABIO!C24+TENJO!C24+SOPO!C24+GACHANCIPA!C24+TOCANCIPA!C24+NEMOCON!C24+COGUA!C24 -> 30335.933 | D24: =CAJICA!D24+COTA!D24+CHIA!D24+ZIPAQUIRA!D24+TABIO!D24+TENJO!D24+SOPO!D24+GACHANCIPA!D24+TOCANCIPA!D24+NEMOCON!D24+COGUA!D24 -> 39670.01 | E24: =CAJICA!E24+COTA!E24+CHIA!E24+ZIPAQUIRA!E24+TABIO!E24+TENJO!E24+SOPO!E24+GACHANCIPA!E24+TOCANCIPA!E24+NEMOCON!E24+COGUA!E24 -> 40700.079 | F24: =CAJICA!F24+COTA!F24+CHIA!F24+ZIPAQUIRA!F24+TABIO!F24+TENJO!F24+SOPO!F24+GACHANCIPA!F24+TOCANCIPA!F24+NEMOCON!F24+COGUA!F24 -> 41829.148 | G24: =CAJICA!G24+COTA!G24+CHIA!G24+ZIPAQUIRA!G24+TABIO!G24+TENJO!G24+SOPO!G24+GACHANCIPA!G24+TOCANCIPA!G24+NEMOCON!G24+COGUA!G24 -> 42318.202 | H24: =CAJICA!H24+COTA!H24+CHIA!H24+ZIPAQUIRA!H24+TABIO!H24+TENJO!H24+SOPO!H24+GACHANCIPA!H24+TOCANCIPA!H24+NEMOCON!H24+COGUA!H24 -> 43357.241 | L24: TASA DE MORTALIDAD POR HOMICIDIO | M24: =CAJICA!M24+COTA!M25+CHIA!M24+ZIPAQUIRA!M24+TABIO!M24+TENJO!M24+SOPO!M24+GACHANCIPA!M24+TOCANCIPA!M24+NEMOCON!M24+COGUA!M24 -> 29 | N24: =M24/C7*100000 -> 6.4838229 | O24: =CAJICA!O24+COTA!O25+CHIA!O24+ZIPAQUIRA!O24+TABIO!O24+TENJO!O24+SOPO!O24+GACHANCIPA!O24+TOCANCIPA!O24+NEMOCON!O24+COGUA!O24 -> 43 | P24: =O24/D7*100000 -> 9.299851 | Q24: =CAJICA!Q24+COTA!Q25+CHIA!Q24+ZIPAQUIRA!Q24+TABIO!Q24+TENJO!Q24+SOPO!Q24+GACHANCIPA!Q24+TOCANCIPA!Q24+NEMOCON!Q24+COGUA!Q24 -> 56 | R24: =Q24/E7*100000 -> 11.741937 | S24: =CAJICA!S24+COTA!S25+CHIA!S24+ZIPAQUIRA!S24+TABIO!S24+TENJO!S24+SOPO!S24+GACHANCIPA!S24+TOCANCIPA!S24+NEMOCON!S24+COGUA!S24 -> 61 | T24: =S24/F7*100000 -> 12.403063 | U24: =CAJICA!U24+COTA!U25+CHIA!U24+ZIPAQUIRA!U24+TABIO!U24+TENJO!U24+SOPO!U24+GACHANCIPA!U24+TOCANCIPA!U24+NEMOCON!U24+COGUA!U24 -> 49 | V24: =U24/G7*100000 -> #VALUE! | W24: =CAJICA!W24+COTA!W25+CHIA!W24+ZIPAQUIRA!W24+TABIO!W24+TENJO!W24+SOPO!W24+GACHANCIPA!W24+TOCANCIPA!W24+NEMOCON!W24+COGUA!W24 -> 27 | X24: =W24/H7*100000 -> 5.1877784 | Y24: =((M24+O24+Q24+S24)/4) -> 47.25 | Z24: =((N24+P24+R24+T24)/4) -> 9.9821685 | AA24: =((S24+U24)/2) -> 55 | AB24: =(V24+X24)/2 -> #VALUE! | AC24: DANE
B25: POBLACION 12 A 17 AÑOS | C25: =CAJICA!C25+COTA!C25+CHIA!C25+ZIPAQUIRA!C25+TABIO!C25+TENJO!C25+SOPO!C25+GACHANCIPA!C25+TOCANCIPA!C25+NEMOCON!C25+COGUA!C25 -> 31549.904 | D25: =CAJICA!D25+COTA!D25+CHIA!D25+ZIPAQUIRA!D25+TABIO!D25+TENJO!D25+SOPO!D25+GACHANCIPA!D25+TOCANCIPA!D25+NEMOCON!D25+COGUA!D25 -> 40434.942 | E25: =CAJICA!E25+COTA!E25+CHIA!E25+ZIPAQUIRA!E25+TABIO!E25+TENJO!E25+SOPO!E25+GACHANCIPA!E25+TOCANCIPA!E25+NEMOCON!E25+COGUA!E25 -> 40935.976 | F25: =CAJICA!F25+COTA!F25+CHIA!F25+ZIPAQUIRA!F25+TABIO!F25+TENJO!F25+SOPO!F25+GACHANCIPA!F25+TOCANCIPA!F25+NEMOCON!F25+COGUA!F25 -> 41544.011 | G25: =CAJICA!G25+COTA!G25+CHIA!G25+ZIPAQUIRA!G25+TABIO!G25+TENJO!G25+SOPO!G25+GACHANCIPA!G25+TOCANCIPA!G25+NEMOCON!G25+COGUA!G25 -> 41813.068 | H25: =CAJICA!H25+COTA!H25+CHIA!H25+ZIPAQUIRA!H25+TABIO!H25+TENJO!H25+SOPO!H25+GACHANCIPA!H25+TOCANCIPA!H25+NEMOCON!H25+COGUA!H25 -> 42602.1 | L25: TASA DE INTENCION SUICIDA | M25: =CAJICA!M25+COTA!M26+CHIA!M25+ZIPAQUIRA!M25+TABIO!M25+TENJO!M25+SOPO!M25+GACHANCIPA!M25+TOCANCIPA!M25+NEMOCON!M25+COGUA!M25 -> 258 | N25: =M25/C7*100000 -> 57.683665 | O25: =CAJICA!O25+COTA!O26+CHIA!O25+ZIPAQUIRA!O25+TABIO!O25+TENJO!O25+SOPO!O25+GACHANCIPA!O25+TOCANCIPA!O25+NEMOCON!O25+COGUA!O25 -> 286 | P25: =O25/D7*100000 -> 61.854823 | Q25: =CAJICA!Q25+COTA!Q26+CHIA!Q25+ZIPAQUIRA!Q25+TABIO!Q25+TENJO!Q25+SOPO!Q25+GACHANCIPA!Q25+TOCANCIPA!Q25+NEMOCON!Q25+COGUA!Q25 -> 373 | R25: =Q25/E7*100000 -> 78.20969 | S25: =CAJICA!S25+COTA!S26+CHIA!S25+ZIPAQUIRA!S25+TABIO!S25+TENJO!S25+SOPO!S25+GACHANCIPA!S25+TOCANCIPA!S25+NEMOCON!S25+COGUA!S25 -> 427 | T25: =S25/F7*100000 -> 86.821441 | U25: =CAJICA!U25+COTA!U26+CHIA!U25+ZIPAQUIRA!U25+TABIO!U25+TENJO!U25+SOPO!U25+GACHANCIPA!U25+TOCANCIPA!U25+NEMOCON!U25+COGUA!U25 -> 442 | V25: =U25/G7*100000 -> #VALUE! | W25: =CAJICA!W25+COTA!W26+CHIA!W25+ZIPAQUIRA!W25+TABIO!W25+TENJO!W25+SOPO!W25+GACHANCIPA!W25+TOCANCIPA!W25+NEMOCON!W25+COGUA!W25 -> 185 | X25: =W25/H7*100000 -> 35.545889 | Y25: =((M25+O25+Q25+S25)/4) -> 336 | Z25: =((N25+P25+R25+T25)/4) -> 71.142405 | AA25: =((S25+U25)/2) -> 434.5 | AB25: =(V25+X25)/2 -> #VALUE! | AC25: SIVIGILA
B26: POBLACION 18 A 28 AÑOS | C26: =CAJICA!C26+COTA!C26+CHIA!C26+ZIPAQUIRA!C26+TABIO!C26+TENJO!C26+SOPO!C26+GACHANCIPA!C26+TOCANCIPA!C26+NEMOCON!C26+COGUA!C26 -> 66281.335 | D26: =CAJICA!D26+COTA!D26+CHIA!D26+ZIPAQUIRA!D26+TABIO!D26+TENJO!D26+SOPO!D26+GACHANCIPA!D26+TOCANCIPA!D26+NEMOCON!D26+COGUA!D26 -> 85038.465 | E26: =CAJICA!E26+COTA!E26+CHIA!E26+ZIPAQUIRA!E26+TABIO!E26+TENJO!E26+SOPO!E26+GACHANCIPA!E26+TOCANCIPA!E26+NEMOCON!E26+COGUA!E26 -> 86338.537 | F26: =CAJICA!F26+COTA!F26+CHIA!F26+ZIPAQUIRA!F26+TABIO!F26+TENJO!F26+SOPO!F26+GACHANCIPA!F26+TOCANCIPA!F26+NEMOCON!F26+COGUA!F26 -> 87231.583 | G26: =CAJICA!G26+COTA!G26+CHIA!G26+ZIPAQUIRA!G26+TABIO!G26+TENJO!G26+SOPO!G26+GACHANCIPA!G26+TOCANCIPA!G26+NEMOCON!G26+COGUA!G26 -> 87401.618 | H26: =CAJICA!H26+COTA!H26+CHIA!H26+ZIPAQUIRA!H26+TABIO!H26+TENJO!H26+SOPO!H26+GACHANCIPA!H26+TOCANCIPA!H26+NEMOCON!H26+COGUA!H26 -> 84542.673 | L26: TASA DE MORTALIDAD PREMATURA (<65 AÑOS) | M26: =CAJICA!M26+COTA!M27+CHIA!M26+ZIPAQUIRA!M26+TABIO!M26+TENJO!M26+SOPO!M26+GACHANCIPA!M26+TOCANCIPA!M26+NEMOCON!M26+COGUA!M26 -> 504 | N26: =M26/C7*100000 -> 112.68437 | O26: =CAJICA!O26+COTA!O27+CHIA!O26+ZIPAQUIRA!O26+TABIO!O26+TENJO!O26+SOPO!O26+GACHANCIPA!O26+TOCANCIPA!O26+NEMOCON!O26+COGUA!O26 -> 861 | P26: =O26/D7*100000 -> 186.2133 | Q26: =CAJICA!Q26+COTA!Q27+CHIA!Q26+ZIPAQUIRA!Q26+TABIO!Q26+TENJO!Q26+SOPO!Q26+GACHANCIPA!Q26+TOCANCIPA!Q26+NEMOCON!Q26+COGUA!Q26 -> 538 | R26: =Q26/E7*100000 -> 112.80647 | S26: =CAJICA!S26+COTA!S27+CHIA!S26+ZIPAQUIRA!S26+TABIO!S26+TENJO!S26+SOPO!S26+GACHANCIPA!S26+TOCANCIPA!S26+NEMOCON!S26+COGUA!S26 -> 425 | T26: =S26/F7*100000 -> 86.414783 | U26: =CAJICA!U26+COTA!U27+CHIA!U26+ZIPAQUIRA!U26+TABIO!U26+TENJO!U26+SOPO!U26+GACHANCIPA!U26+TOCANCIPA!U26+NEMOCON!U26+COGUA!U26 -> 408 | V26: =U26/G7*100000 -> #VALUE! | W26: =CAJICA!W26+COTA!W27+CHIA!W26+ZIPAQUIRA!W26+TABIO!W26+TENJO!W26+SOPO!W26+GACHANCIPA!W26+TOCANCIPA!W26+NEMOCON!W26+COGUA!W26 -> 213 | X26: =W26/H7*100000 -> 40.925807 | Y26: =((M26+O26+Q26+S26)/4) -> 582 | Z26: =((N26+P26+R26+T26)/4) -> 124.52973 | AA26: =((S26+U26)/2) -> 416.5 | AB26: =(V26+X26)/2 -> #VALUE! | AC26: DANE
B27: POBLACION ADULTO MAYOR | C27: =CAJICA!C27+COTA!C27+CHIA!C27+ZIPAQUIRA!C27+TABIO!C27+TENJO!C27+SOPO!C27+GACHANCIPA!C27+TOCANCIPA!C27+NEMOCON!C27+COGUA!C27 -> 39155.477 | D27: =CAJICA!D27+COTA!D27+CHIA!D27+ZIPAQUIRA!D27+TABIO!D27+TENJO!D27+SOPO!D27+GACHANCIPA!D27+TOCANCIPA!D27+NEMOCON!D27+COGUA!D27 -> 37472.561 | E27: =CAJICA!E27+COTA!E27+CHIA!E27+ZIPAQUIRA!E27+TABIO!E27+TENJO!E27+SOPO!E27+GACHANCIPA!E27+TOCANCIPA!E27+NEMOCON!E27+COGUA!E27 -> 42870.642 | F27: =CAJICA!F27+COTA!F27+CHIA!F27+ZIPAQUIRA!F27+TABIO!F27+TENJO!F27+SOPO!F27+GACHANCIPA!F27+TOCANCIPA!F27+NEMOCON!F27+COGUA!F27 -> 45914.727 | G27: =CAJICA!G27+COTA!G27+CHIA!G27+ZIPAQUIRA!G27+TABIO!G27+TENJO!G27+SOPO!G27+GACHANCIPA!G27+TOCANCIPA!G27+NEMOCON!G27+COGUA!G27 -> #VALUE! | H27: =CAJICA!H27+COTA!H27+CHIA!H27+ZIPAQUIRA!H27+TABIO!H27+TENJO!H27+SOPO!H27+GACHANCIPA!H27+TOCANCIPA!H27+NEMOCON!H27+COGUA!H27 -> #VALUE! | L27: TASA DE MORTALIDAD POR CANCER DE CUELLO UTERINO | M27: =CAJICA!M27+COTA!M28+CHIA!M27+ZIPAQUIRA!M27+TABIO!M27+TENJO!M27+SOPO!M27+GACHANCIPA!M27+TOCANCIPA!M27+NEMOCON!M27+COGUA!M27 -> 12 | N27: =M27/C11*100000 -> 5.4247413 | O27: =CAJICA!O27+COTA!O28+CHIA!O27+ZIPAQUIRA!O27+TABIO!O27+TENJO!O27+SOPO!O27+GACHANCIPA!O27+TOCANCIPA!O27+NEMOCON!O27+COGUA!O27 -> 14 | P27: =O27/D11*100000 -> 6.5336664 | Q27: =CAJICA!Q27+COTA!Q28+CHIA!Q27+ZIPAQUIRA!Q27+TABIO!Q27+TENJO!Q27+SOPO!Q27+GACHANCIPA!Q27+TOCANCIPA!Q27+NEMOCON!Q27+COGUA!Q27 -> 14 | R27: =Q27/E11*100000 -> 5.928953 | S27: =CAJICA!S27+COTA!S28+CHIA!S27+ZIPAQUIRA!S27+TABIO!S27+TENJO!S27+SOPO!S27+GACHANCIPA!S27+TOCANCIPA!S27+NEMOCON!S27+COGUA!S27 -> 12 | T27: =S27/F11*100000 -> 4.9401081 | U27: =CAJICA!U27+COTA!U28+CHIA!U27+ZIPAQUIRA!U27+TABIO!U27+TENJO!U27+SOPO!U27+GACHANCIPA!U27+TOCANCIPA!U27+NEMOCON!U27+COGUA!U27 -> 15 | V27: =U27/G11*100000 -> 6.0398645 | W27: =CAJICA!W27+COTA!W28+CHIA!W27+ZIPAQUIRA!W27+TABIO!W27+TENJO!W27+SOPO!W27+GACHANCIPA!W27+TOCANCIPA!W27+NEMOCON!W27+COGUA!W27 -> 2 | X27: =W27/H11*100000 -> 0.78359103 | Y27: =((M27+O27+Q27+S27)/4) -> 13 | Z27: =((N27+P27+R27+T27)/4) -> 5.7068672 | AA27: =((S27+U27)/2) -> 13.5 | AB27: =(V27+X27)/2 -> 3.4117278 | AC27: DANE
L28: TASA DE MORTALIDAD POR CANCER DE MAMA | M28: =CAJICA!M28+COTA!M29+CHIA!M28+ZIPAQUIRA!M28+TABIO!M28+TENJO!M28+SOPO!M28+GACHANCIPA!M28+TOCANCIPA!M28+NEMOCON!M28+COGUA!M28 -> 26 | N28: =M28/C11*100000 -> 11.753606 | O28: =CAJICA!O28+COTA!O29+CHIA!O28+ZIPAQUIRA!O28+TABIO!O28+TENJO!O28+SOPO!O28+GACHANCIPA!O28+TOCANCIPA!O28+NEMOCON!O28+COGUA!O28 -> 29 | P28: =O28/D11*100000 -> 13.534023 | Q28: =CAJICA!Q28+COTA!Q29+CHIA!Q28+ZIPAQUIRA!Q28+TABIO!Q28+TENJO!Q28+SOPO!Q28+GACHANCIPA!Q28+TOCANCIPA!Q28+NEMOCON!Q28+COGUA!Q28 -> 22 | R28: =Q28/E11*100000 -> 9.3169261 | S28: =CAJICA!S28+COTA!S29+CHIA!S28+ZIPAQUIRA!S28+TABIO!S28+TENJO!S28+SOPO!S28+GACHANCIPA!S28+TOCANCIPA!S28+NEMOCON!S28+COGUA!S28 -> 27 | T28: =S28/F11*100000 -> 11.115243 | U28: =CAJICA!U28+COTA!U29+CHIA!U28+ZIPAQUIRA!U28+TABIO!U28+TENJO!U28+SOPO!U28+GACHANCIPA!U28+TOCANCIPA!U28+NEMOCON!U28+COGUA!U28 -> 22 | V28: =U28/G11*100000 -> 8.8584679 | W28: =CAJICA!W28+COTA!W29+CHIA!W28+ZIPAQUIRA!W28+TABIO!W28+TENJO!W28+SOPO!W28+GACHANCIPA!W28+TOCANCIPA!W28+NEMOCON!W28+COGUA!W28 -> 8 | X28: =W28/H11*100000 -> 3.1343641 | Y28: =((M28+O28+Q28+S28)/4) -> 26 | Z28: =((N28+P28+R28+T28)/4) -> 11.42995 | AA28: =((S28+U28)/2) -> 24.5 | AB28: =(V28+X28)/2 -> 5.996416 | AC28: DANE
L29: TASA DE MORTALIDAD POR CANCER DE PROSTATA | M29: =CAJICA!M29+COTA!M30+CHIA!M29+ZIPAQUIRA!M29+TABIO!M29+TENJO!M29+SOPO!M29+GACHANCIPA!M29+TOCANCIPA!M29+NEMOCON!M29+COGUA!M29 -> 44 | N29: =M29/C10*100000 -> 20.934868 | O29: =CAJICA!O29+COTA!O30+CHIA!O29+ZIPAQUIRA!O29+TABIO!O29+TENJO!O29+SOPO!O29+GACHANCIPA!O29+TOCANCIPA!O29+NEMOCON!O29+COGUA!O29 -> 74 | P29: =O29/D10*100000 -> 36.366813 | Q29: =CAJICA!Q29+COTA!Q30+CHIA!Q29+ZIPAQUIRA!Q29+TABIO!Q29+TENJO!Q29+SOPO!Q29+GACHANCIPA!Q29+TOCANCIPA!Q29+NEMOCON!Q29+COGUA!Q29 -> 16 | R29: =Q29/E10*100000 -> #VALUE! | S29: =CAJICA!S29+COTA!S30+CHIA!S29+ZIPAQUIRA!S29+TABIO!S29+TENJO!S29+SOPO!S29+GACHANCIPA!S29+TOCANCIPA!S29+NEMOCON!S29+COGUA!S29 -> 25 | T29: =S29/F10*100000 -> 10.787174 | U29: =CAJICA!U29+COTA!U30+CHIA!U29+ZIPAQUIRA!U29+TABIO!U29+TENJO!U29+SOPO!U29+GACHANCIPA!U29+TOCANCIPA!U29+NEMOCON!U29+COGUA!U29 -> 28 | V29: =U29/G10*100000 -> 11.881776 | W29: =CAJICA!W29+COTA!W30+CHIA!W29+ZIPAQUIRA!W29+TABIO!W29+TENJO!W29+SOPO!W29+GACHANCIPA!W29+TOCANCIPA!W29+NEMOCON!W29+COGUA!W29 -> 11 | X29: =W29/H10*100000 -> 4.5304916 | Y29: =((M29+O29+Q29+S29)/4) -> 39.75 | Z29: =((N29+P29+R29+T29)/4) -> #VALUE! | AA29: =((S29+U29)/2) -> 26.5 | AB29: =(V29+X29)/2 -> 8.2061339 | AC29: DANE
B30: MOMENTO CURSO DE VIDA | C30: AÑO 2020 | D30: AÑO 2021 | E30: AÑO 2022 | F30: AÑO 2023 | G30: AÑO 2024 | H30: AÑO 2025 | L30: TASA DE MORTALIDAD POR ENFERMEDADES TRASMISIBLES | M30: =CAJICA!M30+COTA!M31+CHIA!M30+ZIPAQUIRA!M30+TABIO!M30+TENJO!M30+SOPO!M30+GACHANCIPA!M30+TOCANCIPA!M30+NEMOCON!M30+COGUA!M30 -> 398 | N30: =M30/C7*100000 -> 88.984879 | O30: =CAJICA!O30+COTA!O31+CHIA!O30+ZIPAQUIRA!O30+TABIO!O30+TENJO!O30+SOPO!O30+GACHANCIPA!O30+TOCANCIPA!O30+NEMOCON!O30+COGUA!O30 -> 851 | P30: =O30/D7*100000 -> 184.05054 | Q30: =CAJICA!Q30+COTA!Q31+CHIA!Q30+ZIPAQUIRA!Q30+TABIO!Q30+TENJO!Q30+SOPO!Q30+GACHANCIPA!Q30+TOCANCIPA!Q30+NEMOCON!Q30+COGUA!Q30 -> 166 | R30: =Q30/E7*100000 -> 34.806457 | S30: =CAJICA!S30+COTA!S31+CHIA!S30+ZIPAQUIRA!S30+TABIO!S30+TENJO!S30+SOPO!S30+GACHANCIPA!S30+TOCANCIPA!S30+NEMOCON!S30+COGUA!S30 -> 82 | T30: =S30/F7*100000 -> 16.67297 | U30: =CAJICA!U30+COTA!U31+CHIA!U30+ZIPAQUIRA!U30+TABIO!U30+TENJO!U30+SOPO!U30+GACHANCIPA!U30+TOCANCIPA!U30+NEMOCON!U30+COGUA!U30 -> 104 | V30: =U30/G7*100000 -> #VALUE! | W30: =CAJICA!W30+COTA!W31+CHIA!W30+ZIPAQUIRA!W30+TABIO!W30+TENJO!W30+SOPO!W30+GACHANCIPA!W30+TOCANCIPA!W30+NEMOCON!W30+COGUA!W30 -> 23 | X30: =W30/H7*100000 -> 4.4192186 | Y30: =((M30+O30+Q30+S30)/4) -> 374.25 | Z30: =((N30+P30+R30+T30)/4) -> 81.128711 | AA30: =((S30+U30)/2) -> 93 | AB30: =(V30+X30)/2 -> #VALUE! | AC30: DANE
B31: POBLACION PRIMERA INFANCIA | C31: =CAJICA!C31+COTA!C31+CHIA!C31+ZIPAQUIRA!C31+TABIO!C31+TENJO!C31+SOPO!C31+GACHANCIPA!C31+TOCANCIPA!C31+NEMOCON!C31+COGUA!C31 -> 21129.126 | D31: =CAJICA!D31+COTA!D31+CHIA!D31+ZIPAQUIRA!D31+TABIO!D31+TENJO!D31+SOPO!D31+GACHANCIPA!D31+TOCANCIPA!D31+NEMOCON!D31+COGUA!D31 -> 30527.206 | E31: =CAJICA!E31+COTA!E31+CHIA!E31+ZIPAQUIRA!E31+TABIO!E31+TENJO!E31+SOPO!E31+GACHANCIPA!E31+TOCANCIPA!E31+NEMOCON!E31+COGUA!E31 -> 31006.26 | F31: =CAJICA!F31+COTA!F31+CHIA!F31+ZIPAQUIRA!F31+TABIO!F31+TENJO!F31+SOPO!F31+GACHANCIPA!F31+#REF!+NEMOCON!F31+COGUA!F31 -> #REF! | G31: =CAJICA!G31+COTA!G31+CHIA!G31+ZIPAQUIRA!G31+TABIO!G31+TENJO!G31+SOPO!G31+GACHANCIPA!G31+TOCANCIPA!G31+NEMOCON!G31+COGUA!G31 -> 30641.265 | H31: =CAJICA!H31+COTA!H31+CHIA!H31+ZIPAQUIRA!H31+TABIO!H31+TENJO!H31+SOPO!H31+GACHANCIPA!H31+TOCANCIPA!A31+NEMOCON!H31+COGUA!H31 -> 23683.445 | L31: TASA DE MORTALIDAD POR VIH | M31: =CAJICA!M31+COTA!M32+CHIA!M31+ZIPAQUIRA!M31+TABIO!M31+TENJO!M31+SOPO!M31+GACHANCIPA!M31+TOCANCIPA!M31+NEMOCON!M31+COGUA!M31 -> 27 | N31: =M31/C7*100000 -> 6.0366627 | O31: =CAJICA!O31+COTA!O32+CHIA!O31+ZIPAQUIRA!O31+TABIO!O31+TENJO!O31+SOPO!O31+GACHANCIPA!O31+TOCANCIPA!O31+NEMOCON!O31+COGUA!O31 -> 13 | P31: =O31/D7*100000 -> 2.8115829 | Q31: =CAJICA!Q31+COTA!Q32+CHIA!Q31+ZIPAQUIRA!Q31+TABIO!Q31+TENJO!Q31+SOPO!Q31+GACHANCIPA!Q31+TOCANCIPA!Q31+NEMOCON!Q31+COGUA!Q31 -> 13 | R31: =Q31/E7*100000 -> 2.7258069 | S31: =CAJICA!S31+COTA!S32+CHIA!S31+ZIPAQUIRA!S31+TABIO!S31+TENJO!S31+SOPO!S31+GACHANCIPA!S31+TOCANCIPA!S31+NEMOCON!S31+COGUA!S31 -> 22 | T31: =S31/F7*100000 -> 4.4732358 | U31: =CAJICA!U31+COTA!U32+CHIA!U31+ZIPAQUIRA!U31+TABIO!U31+TENJO!U31+SOPO!U31+GACHANCIPA!U31+TOCANCIPA!U31+NEMOCON!U31+COGUA!U31 -> 14 | V31: =U31/G7*100000 -> #VALUE! | W31: =CAJICA!W31+COTA!W32+CHIA!W31+ZIPAQUIRA!W31+TABIO!W31+TENJO!W31+SOPO!W31+GACHANCIPA!W31+TOCANCIPA!W31+NEMOCON!W31+COGUA!W31 -> 4 | X31: =W31/H7*100000 -> 0.76855976 | Y31: =((M31+O31+Q31+S31)/4) -> 18.75 | Z31: =((N31+P31+R31+T31)/4) -> 4.0118221 | AA31: =((S31+U31)/2) -> 18 | AB31: =(V31+X31)/2 -> #VALUE! | AC31: DANE
B32: POBLACIÓN INFANCIA | C32: =CAJICA!C32+COTA!C32+CHIA!C32+ZIPAQUIRA!C32+TABIO!C32+TENJO!C32+SOPO!C32+GACHANCIPA!C32+TOCANCIPA!C32+NEMOCON!C32+COGUA!C32 -> 17397.933 | D32: =CAJICA!D32+COTA!D32+CHIA!D32+ZIPAQUIRA!D32+TABIO!D32+TENJO!D32+SOPO!D32+GACHANCIPA!D32+TOCANCIPA!D32+NEMOCON!D32+COGUA!D32 -> 26264.01 | E32: =CAJICA!E32+COTA!E32+CHIA!E32+ZIPAQUIRA!E32+TABIO!E32+TENJO!E32+SOPO!E32+GACHANCIPA!E32+TOCANCIPA!A32+NEMOCON!E32+COGUA!E32 -> 22609.079 | F32: =CAJICA!F32+COTA!F32+CHIA!F32+ZIPAQUIRA!F32+TABIO!F32+TENJO!F32+SOPO!F32+GACHANCIPA!F32+TOCANCIPA!F32+NEMOCON!F32+COGUA!F32 -> 27784.148 | G32: =CAJICA!G32+COTA!G32+CHIA!G32+ZIPAQUIRA!G32+TABIO!G32+TENJO!G32+SOPO!G32+GACHANCIPA!G32+TOCANCIPA!G32+NEMOCON!G32+COGUA!G32 -> 27860.202 | H32: =CAJICA!H32+COTA!H32+CHIA!H32+ZIPAQUIRA!H32+TABIO!H32+TENJO!H32+SOPO!H32+GACHANCIPA!H32+TOCANCIPA!H32+NEMOCON!H32+COGUA!H32 -> 25969.844 | L32: PORCENTAJE DE PREVALENCIA VIH | M32: =CAJICA!M32+COTA!M33+CHIA!M32+ZIPAQUIRA!M32+TABIO!M32+TENJO!M32+SOPO!M32+GACHANCIPA!M32+TOCANCIPA!M32+NEMOCON!M32+COGUA!M32 -> 1632 | N32: =M32/C7*100 -> 0.36488272 | O32: =CAJICA!O32+COTA!O33+CHIA!O32+ZIPAQUIRA!O32+TABIO!O32+TENJO!O32+SOPO!O32+GACHANCIPA!O32+TOCANCIPA!O32+NEMOCON!O32+COGUA!O32 -> 2230 | P32: =O32/D7*100 -> 0.4822946 | Q32: =CAJICA!Q32+COTA!Q33+CHIA!Q32+ZIPAQUIRA!Q32+TABIO!Q32+TENJO!Q32+SOPO!Q32+GACHANCIPA!Q32+TOCANCIPA!Q32+NEMOCON!Q32+COGUA!Q32 -> 2232 | R32: =Q32/E7*100 -> 0.46800008 | S32: =CAJICA!S32+COTA!S33+CHIA!S32+ZIPAQUIRA!S32+TABIO!S32+TENJO!S32+SOPO!S32+GACHANCIPA!S32+TOCANCIPA!S32+NEMOCON!S32+COGUA!S32 -> 1918 | T32: =S32/F7*100 -> 0.38998483 | U32: =CAJICA!U32+COTA!U33+CHIA!U32+ZIPAQUIRA!U32+TABIO!U32+TENJO!U32+SOPO!U32+GACHANCIPA!U32+TOCANCIPA!U32+NEMOCON!U32+COGUA!U32 -> 1988 | V32: =U32/G7*100 -> #VALUE! | W32: =CAJICA!W32+COTA!W33+CHIA!W32+ZIPAQUIRA!W32+TABIO!W32+TENJO!W32+SOPO!W32+GACHANCIPA!W32+TOCANCIPA!W32+NEMOCON!W32+COGUA!W32 -> 986 | X32: =W32/H7*100 -> 0.18944998 | Y32: =((M32+O32+Q32+S32)/4) -> 2003 | Z32: =((N32+P32+R32+T32)/4) -> 0.42629056 | AA32: =((S32+U32)/2) -> 1953 | AB32: =(V32+X32)/2 -> #VALUE! | AC32: SIVIGILA
